Workbook

Sheet Customer Input Screen
A2: Crystal Customer Input Screen | C2: MUST ENTER COUNTY OF RESIDENCE
A4: Customer Phone Number | D4: Perform Search by either phone number or first part of name, but not both. Try phone number first
A5: Customer Search First Part of Business Name or Last Name | D5: If you do not get the name you are looking for, then, clear and enter manually
A7: Search Result | C7: =IF(AND(C4="",C5=""),"No Search Entered",IFERROR(VLOOKUP(C4,'Customer List'!A:C,3,FALSE),IFERROR(VLOOKUP(C5,'Customer List'!B:C,2,FALSE),"Not Found Enter Manually"))) -> No Search Entered | I7: Data Used for Invoice
A9: Customer Number | I9: =IF(C9<>0,C9,"") | M9: =IF(C9="","")
A10: Consolidated or Business Name | I10: =IF(C10<>0,C10,"") | M10: =IF(C10="","",C10)
A11: First Name | I11: =IF(C11<>0,C11,"") | M11: =IF(C11="","",C11)
A12: Middle Name | I12: =IF(C12<>0,C12,"") | M12: =IF(C12="","",C12)
A13: Last Name | I13: =IF(C13<>0,C13,"") | M13: =IF(C13="","",C13)
A14: Customer Address | I14: =IF(C14<>0,C14,"") | M14: =IF(C14="","",C14)
A15: Customer Address 2 | I15: =IF(C15<>0,C15,"") | M15: =IF(C15="","",C15)
A16: Customer City | I16: =IF(C16<>0,C16,"") | M16: =IF(C16="","",C16)
A17: Customer State | I17: =IF(C17<>0,C17,"") | M17: =IF(C17="","",C17)
A18: Customer Zip Code | I18: =IF(C18<>0,C18,"") | M18: =IF(C18="","",C18)
A19: Customer Florida County | I19: =IF(C19<>0,C19,"") | M19: =IF(C19="","",C19)
A20: Customer Georgia County | I20: =IF(C20<>0,C20,"") | M20: =IF(C20="","",C20)
A21: Customer Email | I21: =IF(C21<>0,C21,"") | M21: =IF(C21="","",C21)
A22: Customer Cell | I22: =IF(C22<>0,C22,"")
A23: Customer Home | I23: =IF(C23<>0,C23,"") | M23: =IF(C23="",0,C23) -> 0 | P23: =VALUE(Q23) -> 0 | Q23: =IFERROR(VLOOKUP(C$7,'Customer List'!C:AB,14,FALSE),M23) -> 0
A24: Customer Work | I24: =IF(C24<>0,C24,"") | M24: =IF(C24="",0,C24) -> 0
A25: Customer Tax Exempt Number | I25: =IF(C25<>0,C25,"") | M25: =IF(C25="","")
A26: Customer Insurance Company | I26: =IF(C26<>0,C26,"")
A27: Customer Insurance Policy Number | I27: =IF(C27<>0,C27,"")
A28: Customer Insurance Expiration | I28: =IF(C28<>0,C28,"")
A32: Customer Signature | C32: [Customer Signature]
A33: Company Signature | C33: [Company Signature]

Sheet Inventory Look UP
E4: Make | F4: Mod | G4: Desc | H4: Machine Serial # | I4: Group Code
A5: Enter Stock Number | E5: =IFERROR(VLOOKUP($C5,'Inventory Data'!$B$1:$I$9000,3,FALSE),"Not Found") -> Not Found | F5: =IF($E5="Not Found","",IFERROR(VLOOKUP($C5,'Inventory Data'!$B$1:$I$9000,4,FALSE),"Not Found")) | G5: =IF($E5="Not Found","",IFERROR(VLOOKUP($C5,'Inventory Data'!$B$1:$I$9000,5,FALSE),"Not Found")) | H5: =IF($E5="Not Found","",IFERROR(VLOOKUP($C5,'Inventory Data'!$B$1:$I$9000,6,FALSE),"Not Found")) | I5: =IF($E5="Not Found","",IFERROR(VLOOKUP($C5,'Inventory Data'!$B$1:$I$9000,7,FALSE),"Not Found"))
A6: Enter Stock Number | E6: =IFERROR(VLOOKUP($C6,'Inventory Data'!$B$1:$I$9000,3,FALSE),"Not Found") -> Not Found | F6: =IF($E6="Not Found","",IFERROR(VLOOKUP($C6,'Inventory Data'!$B$1:$I$9000,4,FALSE),"Not Found")) | G6: =IF($E6="Not Found","",IFERROR(VLOOKUP($C6,'Inventory Data'!$B$1:$I$9000,5,FALSE),"Not Found")) | H6: =IF($E6="Not Found","",IFERROR(VLOOKUP($C6,'Inventory Data'!$B$1:$I$9000,6,FALSE),"Not Found")) | I6: =IF($E6="Not Found","",IFERROR(VLOOKUP($C6,'Inventory Data'!$B$1:$I$9000,7,FALSE),"Not Found"))
A7: Enter Stock Number | E7: =IFERROR(VLOOKUP($C7,'Inventory Data'!$B$1:$I$9000,3,FALSE),"Not Found") -> Not Found | F7: =IF($E7="Not Found","",IFERROR(VLOOKUP($C7,'Inventory Data'!$B$1:$I$9000,4,FALSE),"Not Found")) | G7: =IF($E7="Not Found","",IFERROR(VLOOKUP($C7,'Inventory Data'!$B$1:$I$9000,5,FALSE),"Not Found")) | H7: =IF($E7="Not Found","",IFERROR(VLOOKUP($C7,'Inventory Data'!$B$1:$I$9000,6,FALSE),"Not Found")) | I7: =IF($E7="Not Found","",IFERROR(VLOOKUP($C7,'Inventory Data'!$B$1:$I$9000,7,FALSE),"Not Found"))
A8: Enter Stock Number | E8: =IFERROR(VLOOKUP($C8,'Inventory Data'!$B$1:$I$9000,3,FALSE),"Not Found") -> Not Found | F8: =IF($E8="Not Found","",IFERROR(VLOOKUP($C8,'Inventory Data'!$B$1:$I$9000,4,FALSE),"Not Found")) | G8: =IF($E8="Not Found","",IFERROR(VLOOKUP($C8,'Inventory Data'!$B$1:$I$9000,5,FALSE),"Not Found")) | H8: =IF($E8="Not Found","",IFERROR(VLOOKUP($C8,'Inventory Data'!$B$1:$I$9000,6,FALSE),"Not Found")) | I8: =IF($E8="Not Found","",IFERROR(VLOOKUP($C8,'Inventory Data'!$B$1:$I$9000,7,FALSE),"Not Found"))
A9: Enter Stock Number | E9: =IFERROR(VLOOKUP($C9,'Inventory Data'!$B$1:$I$9000,3,FALSE),"Not Found") -> Not Found | F9: =IF($E9="Not Found","",IFERROR(VLOOKUP($C9,'Inventory Data'!$B$1:$I$9000,4,FALSE),"Not Found")) | G9: =IF($E9="Not Found","",IFERROR(VLOOKUP($C9,'Inventory Data'!$B$1:$I$9000,5,FALSE),"Not Found")) | H9: =IF($E9="Not Found","",IFERROR(VLOOKUP($C9,'Inventory Data'!$B$1:$I$9000,6,FALSE),"Not Found")) | I9: =IF($E9="Not Found","",IFERROR(VLOOKUP($C9,'Inventory Data'!$B$1:$I$9000,7,FALSE),"Not Found"))
A10: Enter Stock Number | E10: =IFERROR(VLOOKUP($C10,'Inventory Data'!$B$1:$I$9000,3,FALSE),"Not Found") -> Not Found | F10: =IF($E10="Not Found","",IFERROR(VLOOKUP($C10,'Inventory Data'!$B$1:$I$9000,4,FALSE),"Not Found")) | G10: =IF($E10="Not Found","",IFERROR(VLOOKUP($C10,'Inventory Data'!$B$1:$I$9000,5,FALSE),"Not Found")) | H10: =IF($E10="Not Found","",IFERROR(VLOOKUP($C10,'Inventory Data'!$B$1:$I$9000,6,FALSE),"Not Found")) | I10: =IF($E10="Not Found","",IFERROR(VLOOKUP($C10,'Inventory Data'!$B$1:$I$9000,7,FALSE),"Not Found")) | J10: =IF($E10="Not Found","",IFERROR(VLOOKUP($C10,'Inventory Data'!$B$1:$I$9000,8,FALSE),"Not Found"))
A13: Enter Stock Number in Yellow Cells to get Unit Data
A14: Data Good through June 17

Sheet Sales Input Sheet
A2: Must Have a Value in Orange Cells
A3: Fill in all Cells with Possible Data
A6: Store
A8: Customer Number | C8: =+'Customer Input Screen'!I9
A9: Customer Name | C9: =+'Customer Input Screen'!I10
A11: Quote Number
A13: Quote Date
A15: Sales Person
A16: Second Sales Person
I17: Other Description from Table | K17: Other Description from Table | M17: Other Description from Table | O17: FREE FORM DESCRIPTION | U17: Group Code | W17: Type
A18: Stock Number | C18: Make | E18: Model | G18: Serial Number
C19: =+Calculations!B6 | E19: =+Calculations!B7 | G19: =+Calculations!B8 | U19: =Calculations!B618 | W19: =+Calculations!B656
C20: =+Calculations!B18 | E20: =+Calculations!B19 | G20: =+Calculations!B20 | U20: =Calculations!B619 | W20: =+Calculations!B657
C21: =+Calculations!B30 | E21: =+Calculations!B31 | G21: =+Calculations!B32 | U21: =Calculations!B620 | W21: =+Calculations!B658
C22: =+Calculations!B42 | E22: =+Calculations!B43 | G22: =+Calculations!B44 | U22: =Calculations!B621 | W22: =+Calculations!B659
C23: =+Calculations!B54 | E23: =+Calculations!B55 | G23: =+Calculations!B56 | U23: =Calculations!B622 | W23: =+Calculations!B660
C24: =+Calculations!B66 | E24: =+Calculations!B67 | G24: =+Calculations!B68 | U24: =Calculations!B623 | W24: =+Calculations!B661
C25: =+Calculations!B78 | E25: =+Calculations!B79 | G25: =+Calculations!B80 | U25: =Calculations!B624 | W25: =+Calculations!B662
C26: =+Calculations!B90 | E26: =+Calculations!B91 | G26: =+Calculations!B92 | U26: =Calculations!B625 | W26: =+Calculations!B663
C27: =+Calculations!B102 | E27: =+Calculations!B103 | G27: =+Calculations!B104 | U27: =Calculations!B626 | W27: =+Calculations!B664
C28: =+Calculations!B114 | E28: =+Calculations!B115 | G28: =+Calculations!B116 | U28: =Calculations!B627 | W28: =+Calculations!B665
A29: Not In Stock
C30: Make | E30: Model | G30: Serial Number | I30: Description | M30: Other Description
A36: Non Serialized items
A37: Quantity | C37: Make | E37: Model | I37: Part Number | K37: Description from Table | O37: Other Description Free Form
G38: No Serial Number
G39: No Serial Number
G40: No Serial Number
G41: No Serial Number
G42: No Serial Number
A43: Trade In
C44: Make | E44: Model | G44: Serial Number | I44: Lender | K44: Payoff Good Until | M44: Amount Owed | O44: Hours | Q44: Condition | S44: Description
A52: Quanitityof New Tires Sold | E52: Quantity of new tires sold
A53: Quantity of New Batteries Sold | E53: Quantity of new batteries Sold
A55: Additional Information for Invoice Detail
W90: =IF('Finance Manager Input Sheet'!C10="warranty","Store County",IF('Finance Manager Input Sheet'!C10="Extended Service Plan","Store County",""))

Sheet Costing Sheet
A1: Quote Number | C1: =+'Sales Input Sheet'!C11 -> 0
A2: Customer Name | C2: =+Calculations!B3
I3: Commission Split | K3: Tax Exempt | O3: Freight Charge | S3: Customer Accepted Terms before sent to Finance
E5: Sales Person Names | O5: Set Up Fee
E7: =+'Sales Input Sheet'!C15 -> 0 | K7: Sales Tax Exemption Reason 1 | O7: DMV Charges | S7: Customer Accepted Term in Months before Finance Referal | W7: Include Kubota Insurance On Quote | AA7: Yes if Kubota or Land Pride, Elect No as override
A9: Days Until Quote Expiration | E9: =+'Sales Input Sheet'!C16 -> 0 | I9: =+Calculations!B4 -> 1 | K9: SalesTax Exemption Reason 2 | O9: Title Fees | S9: Customer Accepted Interest Rate before Finance Referal | W9: Include Kubota Insurance on Invoice | AA9: Yes if selling Kubota Insurance on Invoice, If selected during Preinvoice
A11: Invoice Date | K11: SalesTax Exemption Reason 3 | O11: Tag Fees | S11: Customer Accepted Down Payment before Finance Referal | U11: =Q17+Q19 -> 0 | W11: Include Kubota Insurance on Refer to Finance | AA11: Kubota Insurance on Menu
A13: Invoice Number | K13: SalesTax Exemption Reason 4 | O13: UCC Fee | S13: Customer Accepted Payment | U13: =Calculations!B449 -> 0
A15: Quote Date | K15: SalesTax Exemption Reason 5 | O15: Doc Stamp Taxes | S15: {=IF(OR('Work a Quote'!F23:F25<>0,'Work a Quote'!D9<>0),"DATA STILL IN WORK A QUOTE, CONFIRM COSTING IS UPDATED AND CLEAR BEFORE PROCEEDING","")}
A17: Sale Type | K17: INCLUDE KUBOTA INSURANCE | O17: ADVANCE DEPOSIT
A19: Customer Primary End User | K19: Rate Table | O19: DOWN PAYMENT DUE AT SIGNING | S19: Purchase Order Number
A21: Stock Number | C21: MAKE | E21: MODEL | G21: Serial Number | I21: Dealer List Price | K21: Discount on Line Item | M21: Net Selling Price | O21: COST | Q21: Incentive Amount | S21: Margin | U21: Incentive Description | W21: Customer Rebate - Reduces Amount due from Customer | Y21: Rebate Description | AA21: MONTHLY KTC INSURANCE RATE | AC21: Suggested KTC Rate | AE21: Cost Adjustment | AG21: Cost Adjustment Description | AI21: We Owe Amount | AK21: We Owe Description | AM21: We Owe Free Form Description | AO21: Accounting Cost Adjustment | AQ21: Accounting Cost Adjustment Description | AS21: Second Incentive Description | AU21: Second Rebate Description | AW21: Second Accounting Cost Adjustment Description
A22: =+'Sales Input Sheet'!A19 -> 0 | C22: =+'Sales Input Sheet'!C19 | E22: =+'Sales Input Sheet'!E19 | G22: =Calculations!B8 | M22: =+Calculations!B526 -> 0 | O22: =Calculations!B11 -> 0 | S22: =+Calculations!B14 -> 0 | AC22: =IF(C22="land Pride",'Admin Input Sheet'!$C$3,IF(AND(C22="Kubota",OR(LEFT(E22,1)="b",LEFT(E22,1)="l",LEFT(E22,1)="f",LEFT(E22,1)="g",AND(LEFT(E22,1)="t",LEFT(E22,2)<>"te",LEFT(E22,3)<>"tlb"),LEFT(E22,1)="w",LEFT(E22,1)="z",LEFT(E22,3)="rtv")),'Admin Input Sheet'!$C$3,'Admin Input Sheet'!$C$4)) -> 0.002
A23: =+'Sales Input Sheet'!A20 -> 0 | C23: =+'Sales Input Sheet'!C20 | E23: =+'Sales Input Sheet'!E20 | G23: =Calculations!B20 | M23: =+Calculations!B527 -> 0 | O23: =Calculations!B23 -> 0 | S23: =+Calculations!B26 -> 0 | AC23: =IF(C23="land Pride",'Admin Input Sheet'!$C$3,IF(AND(C23="Kubota",OR(LEFT(E23,1)="b",LEFT(E23,1)="l",LEFT(E23,1)="f",LEFT(E23,1)="g",AND(LEFT(E23,1)="t",LEFT(E23,2)<>"te",LEFT(E23,3)<>"tlb"),LEFT(E23,1)="w",LEFT(E23,1)="z",LEFT(E23,3)="rtv")),'Admin Input Sheet'!$C$3,'Admin Input Sheet'!$C$4)) -> 0.002
A24: =+'Sales Input Sheet'!A21 -> 0 | C24: =+'Sales Input Sheet'!C21 | E24: =+'Sales Input Sheet'!E21 | G24: =Calculations!B32 | M24: =+Calculations!B528 -> 0 | O24: =Calculations!B35 -> 0 | S24: =+Calculations!B38 -> 0 | AC24: =IF(C24="land Pride",'Admin Input Sheet'!$C$3,IF(AND(C24="Kubota",OR(LEFT(E24,1)="b",LEFT(E24,1)="l",LEFT(E24,1)="f",LEFT(E24,1)="g",AND(LEFT(E24,1)="t",LEFT(E24,2)<>"te",LEFT(E24,3)<>"tlb"),LEFT(E24,1)="w",LEFT(E24,1)="z",LEFT(E24,3)="rtv")),'Admin Input Sheet'!$C$3,'Admin Input Sheet'!$C$4)) -> 0.002
A25: =+'Sales Input Sheet'!A22 -> 0 | C25: =+'Sales Input Sheet'!C22 | E25: =+'Sales Input Sheet'!E22 | G25: =Calculations!B44 | M25: =+Calculations!B529 -> 0 | O25: =Calculations!B47 -> 0 | S25: =+Calculations!B50 -> 0 | AC25: =IF(C25="land Pride",'Admin Input Sheet'!$C$3,IF(AND(C25="Kubota",OR(LEFT(E25,1)="b",LEFT(E25,1)="l",LEFT(E25,1)="f",LEFT(E25,1)="g",AND(LEFT(E25,1)="t",LEFT(E25,2)<>"te",LEFT(E25,3)<>"tlb"),LEFT(E25,1)="w",LEFT(E25,1)="z",LEFT(E25,3)="rtv")),'Admin Input Sheet'!$C$3,'Admin Input Sheet'!$C$4)) -> 0.002
A26: =+'Sales Input Sheet'!A23 -> 0 | C26: =+'Sales Input Sheet'!C23 | E26: =+'Sales Input Sheet'!E23 | G26: =Calculations!B56 | M26: =+Calculations!B530 -> 0 | O26: =Calculations!B59 -> 0 | S26: =+Calculations!B62 -> 0 | AC26: =IF(C26="land Pride",'Admin Input Sheet'!$C$3,IF(AND(C26="Kubota",OR(LEFT(E26,1)="b",LEFT(E26,1)="l",LEFT(E26,1)="f",LEFT(E26,1)="g",AND(LEFT(E26,1)="t",LEFT(E26,2)<>"te",LEFT(E26,3)<>"tlb"),LEFT(E26,1)="w",LEFT(E26,1)="z",LEFT(E26,3)="rtv")),'Admin Input Sheet'!$C$3,'Admin Input Sheet'!$C$4)) -> 0.002
A27: =+'Sales Input Sheet'!A24 -> 0 | C27: =+'Sales Input Sheet'!C24 | E27: =+'Sales Input Sheet'!E24 | G27: =Calculations!B68 | M27: =+Calculations!B531 -> 0 | O27: =Calculations!B71 -> 0 | S27: =+Calculations!B74 -> 0 | AC27: =IF(C27="land Pride",'Admin Input Sheet'!$C$3,IF(AND(C27="Kubota",OR(LEFT(E27,1)="b",LEFT(E27,1)="l",LEFT(E27,1)="f",LEFT(E27,1)="g",AND(LEFT(E27,1)="t",LEFT(E27,2)<>"te",LEFT(E27,3)<>"tlb"),LEFT(E27,1)="w",LEFT(E27,1)="z",LEFT(E27,3)="rtv")),'Admin Input Sheet'!$C$3,'Admin Input Sheet'!$C$4)) -> 0.002
A28: =+'Sales Input Sheet'!A25 -> 0 | C28: =+'Sales Input Sheet'!C25 | E28: =+'Sales Input Sheet'!E25 | G28: =Calculations!B80 | M28: =+Calculations!B532 -> 0 | O28: =Calculations!B83 -> 0 | S28: =+Calculations!B86 -> 0 | AC28: =IF(C28="land Pride",'Admin Input Sheet'!$C$3,IF(AND(C28="Kubota",OR(LEFT(E28,1)="b",LEFT(E28,1)="l",LEFT(E28,1)="f",LEFT(E28,1)="g",AND(LEFT(E28,1)="t",LEFT(E28,2)<>"te",LEFT(E28,3)<>"tlb"),LEFT(E28,1)="w",LEFT(E28,1)="z",LEFT(E28,3)="rtv")),'Admin Input Sheet'!$C$3,'Admin Input Sheet'!$C$4)) -> 0.002
A29: =+'Sales Input Sheet'!A26 -> 0 | C29: =+'Sales Input Sheet'!C26 | E29: =+'Sales Input Sheet'!E26 | G29: =Calculations!B92 | M29: =+Calculations!B533 -> 0 | O29: =Calculations!B95 -> 0 | S29: =+Calculations!B98 -> 0 | AC29: =IF(C29="land Pride",'Admin Input Sheet'!$C$3,IF(AND(C29="Kubota",OR(LEFT(E29,1)="b",LEFT(E29,1)="l",LEFT(E29,1)="f",LEFT(E29,1)="g",AND(LEFT(E29,1)="t",LEFT(E29,2)<>"te",LEFT(E29,3)<>"tlb"),LEFT(E29,1)="w",LEFT(E29,1)="z",LEFT(E29,3)="rtv")),'Admin Input Sheet'!$C$3,'Admin Input Sheet'!$C$4)) -> 0.002
A30: =+'Sales Input Sheet'!A27 -> 0 | C30: =+'Sales Input Sheet'!C27 | E30: =+'Sales Input Sheet'!E27 | G30: =Calculations!B104 | M30: =+Calculations!B534 -> 0 | O30: =Calculations!B107 -> 0 | S30: =+Calculations!B110 -> 0 | AC30: =IF(C30="land Pride",'Admin Input Sheet'!$C$3,IF(AND(C30="Kubota",OR(LEFT(E30,1)="b",LEFT(E30,1)="l",LEFT(E30,1)="f",LEFT(E30,1)="g",AND(LEFT(E30,1)="t",LEFT(E30,2)<>"te",LEFT(E30,3)<>"tlb"),LEFT(E30,1)="w",LEFT(E30,1)="z",LEFT(E30,3)="rtv")),'Admin Input Sheet'!$C$3,'Admin Input Sheet'!$C$4)) -> 0.002
A31: =+'Sales Input Sheet'!A28 -> 0 | C31: =+'Sales Input Sheet'!C28 | E31: =+'Sales Input Sheet'!E28 | G31: =Calculations!B116 | M31: =+Calculations!B535 -> 0 | O31: =Calculations!B119 -> 0 | S31: =+Calculations!B122 -> 0 | AC31: =IF(C31="land Pride",'Admin Input Sheet'!$C$3,IF(AND(C31="Kubota",OR(LEFT(E31,1)="b",LEFT(E31,1)="l",LEFT(E31,1)="f",LEFT(E31,1)="g",AND(LEFT(E31,1)="t",LEFT(E31,2)<>"te",LEFT(E31,3)<>"tlb"),LEFT(E31,1)="w",LEFT(E31,1)="z",LEFT(E31,3)="rtv")),'Admin Input Sheet'!$C$3,'Admin Input Sheet'!$C$4)) -> 0.002
A33: Write In Items | C33: MAKE | E33: MODEL | G33: Serial Number | I33: Dealer List Price | K33: Discount on Line Item | M33: Net Selling Price | O33: COST | Q33: Incentive Amount | S33: Margin | U33: Incentive Description | W33: Customer Rebate - Reduces Amount due from Customer | Y33: Rebate Description | AA33: MONTHLY KTC INSURANCE RATE | AE33: Accounting Cost Adjustment | AG33: Accounting Cost Adjustment Description | AS33: Second Incentive Description | AU33: Second Rebate Description | AW33: Second Accounting Cost Adjustment Description
C34: =+'Sales Input Sheet'!C31 -> 0 | E34: =+'Sales Input Sheet'!E31 -> 0 | G34: =+'Sales Input Sheet'!G31 -> 0 | M34: =+Calculations!B536 -> 0 | S34: =Calculations!B126 -> 0 | AC34: =IF(C34="land Pride",'Admin Input Sheet'!$C$3,IF(AND(C34="Kubota",OR(LEFT(E34,1)="b",LEFT(E34,1)="l",LEFT(E34,1)="f",LEFT(E34,1)="g",AND(LEFT(E34,1)="t",LEFT(E34,2)<>"te",LEFT(E34,3)<>"tlb"),LEFT(E34,1)="w",LEFT(E34,1)="z",LEFT(E34,3)="rtv")),'Admin Input Sheet'!$C$3,'Admin Input Sheet'!$C$4)) -> 0.002
C35: =+'Sales Input Sheet'!C32 -> 0 | E35: =+'Sales Input Sheet'!E32 -> 0 | G35: =+'Sales Input Sheet'!G32 -> 0 | M35: =+Calculations!B537 -> 0 | S35: =Calculations!B130 -> 0 | AC35: =IF(C35="land Pride",'Admin Input Sheet'!$C$3,IF(AND(C35="Kubota",OR(LEFT(E35,1)="b",LEFT(E35,1)="l",LEFT(E35,1)="f",LEFT(E35,1)="g",AND(LEFT(E35,1)="t",LEFT(E35,2)<>"te",LEFT(E35,3)<>"tlb"),LEFT(E35,1)="w",LEFT(E35,1)="z",LEFT(E35,3)="rtv")),'Admin Input Sheet'!$C$3,'Admin Input Sheet'!$C$4)) -> 0.002
C36: =+'Sales Input Sheet'!C33 -> 0 | E36: =+'Sales Input Sheet'!E33 -> 0 | G36: =+'Sales Input Sheet'!G33 -> 0 | M36: =+Calculations!B538 -> 0 | S36: =Calculations!B134 -> 0 | AC36: =IF(C36="land Pride",'Admin Input Sheet'!$C$3,IF(AND(C36="Kubota",OR(LEFT(E36,1)="b",LEFT(E36,1)="l",LEFT(E36,1)="f",LEFT(E36,1)="g",AND(LEFT(E36,1)="t",LEFT(E36,2)<>"te",LEFT(E36,3)<>"tlb"),LEFT(E36,1)="w",LEFT(E36,1)="z",LEFT(E36,3)="rtv")),'Admin Input Sheet'!$C$3,'Admin Input Sheet'!$C$4)) -> 0.002
C37: =+'Sales Input Sheet'!C34 -> 0 | E37: =+'Sales Input Sheet'!E34 -> 0 | G37: =+'Sales Input Sheet'!G34 -> 0 | M37: =+Calculations!B539 -> 0 | S37: =Calculations!B138 -> 0 | AC37: =IF(C37="land Pride",'Admin Input Sheet'!$C$3,IF(AND(C37="Kubota",OR(LEFT(E37,1)="b",LEFT(E37,1)="l",LEFT(E37,1)="f",LEFT(E37,1)="g",AND(LEFT(E37,1)="t",LEFT(E37,2)<>"te",LEFT(E37,3)<>"tlb"),LEFT(E37,1)="w",LEFT(E37,1)="z",LEFT(E37,3)="rtv")),'Admin Input Sheet'!$C$3,'Admin Input Sheet'!$C$4)) -> 0.002
C38: =+'Sales Input Sheet'!C35 -> 0 | E38: =+'Sales Input Sheet'!E35 -> 0 | G38: =+'Sales Input Sheet'!G35 -> 0 | M38: =+Calculations!B540 -> 0 | S38: =Calculations!B142 -> 0 | AC38: =IF(C38="land Pride",'Admin Input Sheet'!$C$3,IF(AND(C38="Kubota",OR(LEFT(E38,1)="b",LEFT(E38,1)="l",LEFT(E38,1)="f",LEFT(E38,1)="g",AND(LEFT(E38,1)="t",LEFT(E38,2)<>"te",LEFT(E38,3)<>"tlb"),LEFT(E38,1)="w",LEFT(E38,1)="z",LEFT(E38,3)="rtv")),'Admin Input Sheet'!$C$3,'Admin Input Sheet'!$C$4)) -> 0.002
A40: Non Serialied Items
A41: Quantity Sold | C41: MAKE | E41: MODEL | G41: Part Number | I41: Dealer List Price Per Unit | K41: Discount Line Item per unit | M41: Net Extended Selling Price | O41: COST per Item | S41: Extended Margin | AA41: MONTHLY KTC INSURANCE RATE
A42: =+'Sales Input Sheet'!A38 -> 0 | C42: =+'Sales Input Sheet'!C38 -> 0 | E42: =+'Sales Input Sheet'!E38 -> 0 | G42: =+'Sales Input Sheet'!I38 -> 0 | M42: =+Calculations!B541 -> 0 | S42: =Calculations!B146 -> 0 | AC42: =IF(C42="land Pride",'Admin Input Sheet'!$C$3,IF(AND(C42="Kubota",OR(LEFT(E42,1)="b",LEFT(E42,1)="l",LEFT(E42,1)="f",LEFT(E42,1)="g",AND(LEFT(E42,1)="t",LEFT(E42,2)<>"te",LEFT(E42,3)<>"tlb"),LEFT(E42,1)="w",LEFT(E42,1)="z",LEFT(E42,3)="rtv")),'Admin Input Sheet'!$C$3,'Admin Input Sheet'!$C$4)) -> 0.002
A43: =+'Sales Input Sheet'!A39 -> 0 | C43: =+'Sales Input Sheet'!C39 -> 0 | E43: =+'Sales Input Sheet'!E39 -> 0 | G43: =+'Sales Input Sheet'!I39 -> 0 | M43: =+Calculations!B542 -> 0 | S43: =Calculations!B154 -> 0 | AC43: =IF(C43="land Pride",'Admin Input Sheet'!$C$3,IF(AND(C43="Kubota",OR(LEFT(E43,1)="b",LEFT(E43,1)="l",LEFT(E43,1)="f",LEFT(E43,1)="g",AND(LEFT(E43,1)="t",LEFT(E43,2)<>"te",LEFT(E43,3)<>"tlb"),LEFT(E43,1)="w",LEFT(E43,1)="z",LEFT(E43,3)="rtv")),'Admin Input Sheet'!$C$3,'Admin Input Sheet'!$C$4)) -> 0.002
A44: =+'Sales Input Sheet'!A40 -> 0 | C44: =+'Sales Input Sheet'!C40 -> 0 | E44: =+'Sales Input Sheet'!E40 -> 0 | G44: =+'Sales Input Sheet'!I40 -> 0 | M44: =+Calculations!B543 -> 0 | S44: =Calculations!B162 -> 0 | AC44: =IF(C44="land Pride",'Admin Input Sheet'!$C$3,IF(AND(C44="Kubota",OR(LEFT(E44,1)="b",LEFT(E44,1)="l",LEFT(E44,1)="f",LEFT(E44,1)="g",AND(LEFT(E44,1)="t",LEFT(E44,2)<>"te",LEFT(E44,3)<>"tlb"),LEFT(E44,1)="w",LEFT(E44,1)="z",LEFT(E44,3)="rtv")),'Admin Input Sheet'!$C$3,'Admin Input Sheet'!$C$4)) -> 0.002
A45: =+'Sales Input Sheet'!A41 -> 0 | C45: =+'Sales Input Sheet'!C41 -> 0 | E45: =+'Sales Input Sheet'!E41 -> 0 | G45: =+'Sales Input Sheet'!I41 -> 0 | M45: =+Calculations!B544 -> 0 | S45: =Calculations!B170 -> 0 | AC45: =IF(C45="land Pride",'Admin Input Sheet'!$C$3,IF(AND(C45="Kubota",OR(LEFT(E45,1)="b",LEFT(E45,1)="l",LEFT(E45,1)="f",LEFT(E45,1)="g",AND(LEFT(E45,1)="t",LEFT(E45,2)<>"te",LEFT(E45,3)<>"tlb"),LEFT(E45,1)="w",LEFT(E45,1)="z",LEFT(E45,3)="rtv")),'Admin Input Sheet'!$C$3,'Admin Input Sheet'!$C$4)) -> 0.002
A46: =+'Sales Input Sheet'!A42 -> 0 | C46: =+'Sales Input Sheet'!C42 -> 0 | E46: =+'Sales Input Sheet'!E42 -> 0 | G46: =+'Sales Input Sheet'!I42 -> 0 | M46: =+Calculations!B545 -> 0 | S46: =Calculations!B178 -> 0 | AC46: =IF(C46="land Pride",'Admin Input Sheet'!$C$3,IF(AND(C46="Kubota",OR(LEFT(E46,1)="b",LEFT(E46,1)="l",LEFT(E46,1)="f",LEFT(E46,1)="g",AND(LEFT(E46,1)="t",LEFT(E46,2)<>"te",LEFT(E46,3)<>"tlb"),LEFT(E46,1)="w",LEFT(E46,1)="z",LEFT(E46,3)="rtv")),'Admin Input Sheet'!$C$3,'Admin Input Sheet'!$C$4)) -> 0.002
A47: Trade In
C48: Make | E48: Model | G48: Serial Number | I48: Trade Allowance | K48: Amount Owed | M48: =+'Sales Input Sheet'!Q44 -> Condition | O48: Trade ACV Value | Q48: =+'Sales Input Sheet'!O44 -> Hours | S48: Margin | U48: Disposition Plan | AA48: Reduce Taxable Amount by Trade Allowance
C49: =+'Sales Input Sheet'!C45 -> 0 | E49: =+'Sales Input Sheet'!E45 -> 0 | G49: =+'Sales Input Sheet'!G45 -> 0 | M49: =+'Sales Input Sheet'!Q45 -> 0 | Q49: =+'Sales Input Sheet'!O45 -> 0 | S49: =+Calculations!B185 -> 0
C50: =+'Sales Input Sheet'!C46 -> 0 | E50: =+'Sales Input Sheet'!E46 -> 0 | G50: =+'Sales Input Sheet'!G46 -> 0 | M50: =+'Sales Input Sheet'!Q46 -> 0 | Q50: =+'Sales Input Sheet'!O46 -> 0 | S50: =+Calculations!B186 -> 0
C51: =+'Sales Input Sheet'!C47 -> 0 | E51: =+'Sales Input Sheet'!E47 -> 0 | G51: =+'Sales Input Sheet'!G47 -> 0 | M51: =+'Sales Input Sheet'!Q47 -> 0 | Q51: =+'Sales Input Sheet'!O47 -> 0 | S51: =+Calculations!B666 -> 0
...

Sheet Finance Manager Input Sheet
A2: Quote Number | C2: =+'Sales Input Sheet'!C11 -> 0 | E2: Finance Manager
C3: PRODUCT NAME | E3: Term and Expanded Description | G3: Seller of Product | I3: Selling Price | K3: Cost if Accepted | N3: Customer Accepted | P3: Margin | R3: Platinum Package | T3: Gold Package | V3: Silver Package | X3: Bronze Package | AA3: Platinum Plan | AB3: Platinum Selling Price without Tax | AC3: Platinum Price with Tax | AD3: Platinum Cost | AE3: Gold Plan | AF3: Gold Plan Price | AG3: Gold Price with Tax | AH3: GoldCost | AI3: Silver Plan | AJ3: SILVER PLAN PRICE | AK3: Silver Price with tax | AL3: Silver Cost | AM3: Bronze Plan | AN3: Bronze Plan Price | AO3: Bronze Price with tax | AP3: Bronze Cost | AQ3: Customer Accepted Protection Options | AR3: Customer Accepted Price | AS3: Accepted Price with tax | AT3: Accepted Cost | AU3: Customer Declined Protection Options | AV3: Customer Decline Price | AW3: Desc | AX3: Price with Tax | AY3: Cost | BA3: Customer Accepted | BB3: Customer Declined | BD3: Platinum | BF3: Gold | BH3: Silver | BJ3: Bronze
A4: Additional Product Sale | P4: =IF(N4="no",0,I4-K4) -> 0 | AA4: =IF(I4>0,IF($BD4<>"no",IF(C4<>0,UPPER(_xlfn.CONCAT(E4," ",C4)),""),""),"") | AB4: =IF($R4<>"no",IF(I4<>0,$I4,0),0) -> 0 | AC4: =IF($R4<>"no",IF($AX4<>0,$AX4,0),0) -> 0 | AD4: =IF($R4<>"no",IF($AY4<>0,$AY4,0),0) -> 0 | AE4: =IF(I4>0,IF($BF4<>"no",IF(C4<>0,UPPER(_xlfn.CONCAT(E4," ",C4)),""),""),"") | AF4: =IF($T4<>"no",IF(I4<>0,I4,0),0) -> 0 | AG4: =IF($T4<>"no",IF($AX4<>0,$AX4,0),0) -> 0 | AH4: =IF($T4<>"no",IF($AY4<>0,$AY4,0),0) -> 0 | AI4: =IF(I4>0,IF($BH4<>"no",IF(C4<>0,UPPER(_xlfn.CONCAT(E4," ",C4)),""),""),"") | AJ4: =IF($V4<>"no",IF($I4<>0,$I4,0),0) -> 0 | AK4: =IF($V4<>"no",IF($AX4<>0,$AX4,0),0) -> 0 | AL4: =IF($V4<>"no",IF($AY4<>0,$AY4,0),0) -> 0 | AM4: =IF(I4>0,IF($BJ4<>"no",IF(C4<>0,UPPER(_xlfn.CONCAT(E4," ",C4)),""),""),"") | AN4: =IF($X4<>"no",IF($I4<>0,$I4,0),0) -> 0 | AO4: =IF($X4<>"no",IF($AX4<>0,$AX4,0),0) -> 0 | AP4: =IF($X4<>"no",IF($AY4<>0,$AY4,0),0) -> 0 | AQ4: =IF(I4>0,IF($N4<>"no",IF(C4<>0,UPPER(_xlfn.CONCAT(E4," ",C4)),""),""),"") | AR4: =IF(N4<>"no",IF($I4<>0,$I4,0),0) -> 0 | AS4: =IF(N4<>"no",IF($AX4<>0,$AX4,0),0) -> 0 | AT4: =IF($N4<>"no",IF($AY4<>0,$AY4,0),0) -> 0 | AU4: =IF(I4>0,IF($N4="no",IF(C4<>0,UPPER(_xlfn.CONCAT(E4," ",C4)),""),""),"") | AW4: =_xlfn.CONCAT(C4) | AX4: =I4*(1+IF('Costing Sheet'!M3="Tax Exempt",0,IF(IFERROR(VLOOKUP(C4,'Admin Input Sheet'!C$9:I$18,3,FALSE),"Taxable")="Taxable",Calculations!B$404,0)+IF(IFERROR(VLOOKUP(C4,'Admin Input Sheet'!C$9:I$18,IF(Calculations!B402="FL",5,7),FALSE),"Store")="No County Tax",0,IF(IFERROR(VLOOKUP(C4,'Admin Input Sheet'!C$9:I$18,IF(Calculations!B402="FL",5,7),FALSE),"Store")="Customer",Calculations!B$410,Calculations!B$408)))) -> 0 | AY4: =K4 -> 0 | BA4: =IF(N4="No","Customer Declined",IF($I4>0,N4,"NO")) -> NO | BB4: =IF(AND(I4>0,N4="No"),"Customer Declined","No") -> No | BD4: =IF($I4>0,R4,"No") -> No | BF4: =IF($I4>0,T4,"No") -> No | BH4: =IF($I4>0,V4,"No") -> No | BJ4: =IF($I4>0,X4,"No") -> No
A5: Additional Product Sale | P5: =IF(N5="no",0,I5-K5) -> 0 | AA5: =IF(I5>0,IF($BD5<>"no",IF(C5<>0,UPPER(_xlfn.CONCAT(E5," ",C5)),""),""),"") | AB5: =IF($R5<>"no",IF(I5<>0,$I5,0),0) -> 0 | AC5: =IF($R5<>"no",IF($AX5<>0,$AX5,0),0) -> 0 | AD5: =IF($R5<>"no",IF($AY5<>0,$AY5,0),0) -> 0 | AE5: =IF(I5>0,IF($BF5<>"no",IF(C5<>0,UPPER(_xlfn.CONCAT(E5," ",C5)),""),""),"") | AF5: =IF($T5<>"no",IF(I5<>0,I5,0),0) -> 0 | AG5: =IF($T5<>"no",IF($AX5<>0,$AX5,0),0) -> 0 | AH5: =IF($T5<>"no",IF($AY5<>0,$AY5,0),0) -> 0 | AI5: =IF(I5>0,IF($BH5<>"no",IF(C5<>0,UPPER(_xlfn.CONCAT(E5," ",C5)),""),""),"") | AJ5: =IF($V5<>"no",IF($I5<>0,$I5,0),0) -> 0 | AK5: =IF($V5<>"no",IF($AX5<>0,$AX5,0),0) -> 0 | AL5: =IF($V5<>"no",IF($AY5<>0,$AY5,0),0) -> 0 | AM5: =IF(I5>0,IF($BJ5<>"no",IF(C5<>0,UPPER(_xlfn.CONCAT(E5," ",C5)),""),""),"") | AN5: =IF($X5<>"no",IF($I5<>0,$I5,0),0) -> 0 | AO5: =IF($X5<>"no",IF($AX5<>0,$AX5,0),0) -> 0 | AP5: =IF($X5<>"no",IF($AY5<>0,$AY5,0),0) -> 0 | AQ5: =IF(I5>0,IF($N5<>"no",IF(C5<>0,UPPER(_xlfn.CONCAT(E5," ",C5)),""),""),"") | AR5: =IF(N5<>"no",IF($I5<>0,$I5,0),0) -> 0 | AS5: =IF(N5<>"no",IF($AX5<>0,$AX5,0),0) -> 0 | AT5: =IF($N5<>"no",IF($AY5<>0,$AY5,0),0) -> 0 | AU5: =IF(I5>0,IF($N5="no",IF(C5<>0,UPPER(_xlfn.CONCAT(E5," ",C5)),""),""),"") | AW5: =_xlfn.CONCAT(C5) | AX5: =I5*(1+IF('Costing Sheet'!M4="Tax Exempt",0,IF(IFERROR(VLOOKUP(C5,'Admin Input Sheet'!C$9:I$18,3,FALSE),"Taxable")="Taxable",Calculations!B$404,0)+IF(IFERROR(VLOOKUP(C5,'Admin Input Sheet'!C$9:I$18,IF(Calculations!B403="FL",5,7),FALSE),"Store")="No County Tax",0,IF(IFERROR(VLOOKUP(C5,'Admin Input Sheet'!C$9:I$18,IF(Calculations!B403="FL",5,7),FALSE),"Store")="Customer",Calculations!B$410,Calculations!B$408)))) -> 0 | AY5: =K5 -> 0 | BA5: =IF(N5="No","Customer Declined",IF($I5>0,N5,"NO")) -> NO | BB5: =IF(AND(I5>0,N5="No"),"Customer Declined","No") -> No | BD5: =IF($I5>0,R5,"No") -> No | BF5: =IF($I5>0,T5,"No") -> No | BH5: =IF($I5>0,V5,"No") -> No | BJ5: =IF($I5>0,X5,"No") -> No
A6: Additional Product Sale | P6: =IF(N6="no",0,I6-K6) -> 0 | AA6: =IF(I6>0,IF($BD6<>"no",IF(C6<>0,UPPER(_xlfn.CONCAT(E6," ",C6)),""),""),"") | AB6: =IF($R6<>"no",IF(I6<>0,$I6,0),0) -> 0 | AC6: =IF($R6<>"no",IF($AX6<>0,$AX6,0),0) -> 0 | AD6: =IF($R6<>"no",IF($AY6<>0,$AY6,0),0) -> 0 | AE6: =IF(I6>0,IF($BF6<>"no",IF(C6<>0,UPPER(_xlfn.CONCAT(E6," ",C6)),""),""),"") | AF6: =IF($T6<>"no",IF(I6<>0,I6,0),0) -> 0 | AG6: =IF($T6<>"no",IF($AX6<>0,$AX6,0),0) -> 0 | AH6: =IF($T6<>"no",IF($AY6<>0,$AY6,0),0) -> 0 | AI6: =IF(I6>0,IF($BH6<>"no",IF(C6<>0,UPPER(_xlfn.CONCAT(E6," ",C6)),""),""),"") | AJ6: =IF($V6<>"no",IF($I6<>0,$I6,0),0) -> 0 | AK6: =IF($V6<>"no",IF($AX6<>0,$AX6,0),0) -> 0 | AL6: =IF($V6<>"no",IF($AY6<>0,$AY6,0),0) -> 0 | AM6: =IF(I6>0,IF($BJ6<>"no",IF(C6<>0,UPPER(_xlfn.CONCAT(E6," ",C6)),""),""),"") | AN6: =IF($X6<>"no",IF($I6<>0,$I6,0),0) -> 0 | AO6: =IF($X6<>"no",IF($AX6<>0,$AX6,0),0) -> 0 | AP6: =IF($X6<>"no",IF($AY6<>0,$AY6,0),0) -> 0 | AQ6: =IF(I6>0,IF($N6<>"no",IF(C6<>0,UPPER(_xlfn.CONCAT(E6," ",C6)),""),""),"") | AR6: =IF(N6<>"no",IF($I6<>0,$I6,0),0) -> 0 | AS6: =IF(N6<>"no",IF($AX6<>0,$AX6,0),0) -> 0 | AT6: =IF($N6<>"no",IF($AY6<>0,$AY6,0),0) -> 0 | AU6: =IF(I6>0,IF($N6="no",IF(C6<>0,UPPER(_xlfn.CONCAT(E6," ",C6)),""),""),"") | AW6: =_xlfn.CONCAT(C6) | AX6: =I6*(1+IF('Costing Sheet'!M5="Tax Exempt",0,IF(IFERROR(VLOOKUP(C6,'Admin Input Sheet'!C$9:I$18,3,FALSE),"Taxable")="Taxable",Calculations!B$404,0)+IF(IFERROR(VLOOKUP(C6,'Admin Input Sheet'!C$9:I$18,IF(Calculations!B404="FL",5,7),FALSE),"Store")="No County Tax",0,IF(IFERROR(VLOOKUP(C6,'Admin Input Sheet'!C$9:I$18,IF(Calculations!B404="FL",5,7),FALSE),"Store")="Customer",Calculations!B$410,Calculations!B$408)))) -> 0 | AY6: =K6 -> 0 | BA6: =IF(N6="No","Customer Declined",IF($I6>0,N6,"NO")) -> NO | BB6: =IF(AND(I6>0,N6="No"),"Customer Declined","No") -> No | BD6: =IF($I6>0,R6,"No") -> No | BF6: =IF($I6>0,T6,"No") -> No | BH6: =IF($I6>0,V6,"No") -> No | BJ6: =IF($I6>0,X6,"No") -> No
A7: Additional Product Sale | P7: =IF(N7="no",0,I7-K7) -> 0 | AA7: =IF(I7>0,IF($BD7<>"no",IF(C7<>0,UPPER(_xlfn.CONCAT(E7," ",C7)),""),""),"") | AB7: =IF($R7<>"no",IF(I7<>0,$I7,0),0) -> 0 | AC7: =IF($R7<>"no",IF($AX7<>0,$AX7,0),0) -> 0 | AD7: =IF($R7<>"no",IF($AY7<>0,$AY7,0),0) -> 0 | AE7: =IF(I7>0,IF($BF7<>"no",IF(C7<>0,UPPER(_xlfn.CONCAT(E7," ",C7)),""),""),"") | AF7: =IF($T7<>"no",IF(I7<>0,I7,0),0) -> 0 | AG7: =IF($T7<>"no",IF($AX7<>0,$AX7,0),0) -> 0 | AH7: =IF($T7<>"no",IF($AY7<>0,$AY7,0),0) -> 0 | AI7: =IF(I7>0,IF($BH7<>"no",IF(C7<>0,UPPER(_xlfn.CONCAT(E7," ",C7)),""),""),"") | AJ7: =IF($V7<>"no",IF($I7<>0,$I7,0),0) -> 0 | AK7: =IF($V7<>"no",IF($AX7<>0,$AX7,0),0) -> 0 | AL7: =IF($V7<>"no",IF($AY7<>0,$AY7,0),0) -> 0 | AM7: =IF(I7>0,IF($BJ7<>"no",IF(C7<>0,UPPER(_xlfn.CONCAT(E7," ",C7)),""),""),"") | AN7: =IF($X7<>"no",IF($I7<>0,$I7,0),0) -> 0 | AO7: =IF($X7<>"no",IF($AX7<>0,$AX7,0),0) -> 0 | AP7: =IF($X7<>"no",IF($AY7<>0,$AY7,0),0) -> 0 | AQ7: =IF(I7>0,IF($N7<>"no",IF(C7<>0,UPPER(_xlfn.CONCAT(E7," ",C7)),""),""),"") | AR7: =IF(N7<>"no",IF($I7<>0,$I7,0),0) -> 0 | AS7: =IF(N7<>"no",IF($AX7<>0,$AX7,0),0) -> 0 | AT7: =IF($N7<>"no",IF($AY7<>0,$AY7,0),0) -> 0 | AU7: =IF(I7>0,IF($N7="no",IF(C7<>0,UPPER(_xlfn.CONCAT(E7," ",C7)),""),""),"") | AW7: =_xlfn.CONCAT(C7) | AX7: =I7*(1+IF('Costing Sheet'!M6="Tax Exempt",0,IF(IFERROR(VLOOKUP(C7,'Admin Input Sheet'!C$9:I$18,3,FALSE),"Taxable")="Taxable",Calculations!B$404,0)+IF(IFERROR(VLOOKUP(C7,'Admin Input Sheet'!C$9:I$18,IF(Calculations!B405="FL",5,7),FALSE),"Store")="No County Tax",0,IF(IFERROR(VLOOKUP(C7,'Admin Input Sheet'!C$9:I$18,IF(Calculations!B405="FL",5,7),FALSE),"Store")="Customer",Calculations!B$410,Calculations!B$408)))) -> 0 | AY7: =K7 -> 0 | BA7: =IF(N7="No","Customer Declined",IF($I7>0,N7,"NO")) -> NO | BB7: =IF(AND(I7>0,N7="No"),"Customer Declined","No") -> No | BD7: =IF($I7>0,R7,"No") -> No | BF7: =IF($I7>0,T7,"No") -> No | BH7: =IF($I7>0,V7,"No") -> No | BJ7: =IF($I7>0,X7,"No") -> No
A8: Additional Product Sale | P8: =IF(N8="no",0,I8-K8) -> 0 | AA8: =IF(I8>0,IF($BD8<>"no",IF(C8<>0,UPPER(_xlfn.CONCAT(E8," ",C8)),""),""),"") | AB8: =IF($R8<>"no",IF(I8<>0,$I8,0),0) -> 0 | AC8: =IF($R8<>"no",IF($AX8<>0,$AX8,0),0) -> 0 | AD8: =IF($R8<>"no",IF($AY8<>0,$AY8,0),0) -> 0 | AE8: =IF(I8>0,IF($BF8<>"no",IF(C8<>0,UPPER(_xlfn.CONCAT(E8," ",C8)),""),""),"") | AF8: =IF($T8<>"no",IF(I8<>0,I8,0),0) -> 0 | AG8: =IF($T8<>"no",IF($AX8<>0,$AX8,0),0) -> 0 | AH8: =IF($T8<>"no",IF($AY8<>0,$AY8,0),0) -> 0 | AI8: =IF(I8>0,IF($BH8<>"no",IF(C8<>0,UPPER(_xlfn.CONCAT(E8," ",C8)),""),""),"") | AJ8: =IF($V8<>"no",IF($I8<>0,$I8,0),0) -> 0 | AK8: =IF($V8<>"no",IF($AX8<>0,$AX8,0),0) -> 0 | AL8: =IF($V8<>"no",IF($AY8<>0,$AY8,0),0) -> 0 | AM8: =IF(I8>0,IF($BJ8<>"no",IF(C8<>0,UPPER(_xlfn.CONCAT(E8," ",C8)),""),""),"") | AN8: =IF($X8<>"no",IF($I8<>0,$I8,0),0) -> 0 | AO8: =IF($X8<>"no",IF($AX8<>0,$AX8,0),0) -> 0 | AP8: =IF($X8<>"no",IF($AY8<>0,$AY8,0),0) -> 0 | AQ8: =IF(I8>0,IF($N8<>"no",IF(C8<>0,UPPER(_xlfn.CONCAT(E8," ",C8)),""),""),"") | AR8: =IF(N8<>"no",IF($I8<>0,$I8,0),0) -> 0 | AS8: =IF(N8<>"no",IF($AX8<>0,$AX8,0),0) -> 0 | AT8: =IF($N8<>"no",IF($AY8<>0,$AY8,0),0) -> 0 | AU8: =IF(I8>0,IF($N8="no",IF(C8<>0,UPPER(_xlfn.CONCAT(E8," ",C8)),""),""),"") | AW8: =_xlfn.CONCAT(C8) | AX8: =I8*(1+IF('Costing Sheet'!M7="Tax Exempt",0,IF(IFERROR(VLOOKUP(C8,'Admin Input Sheet'!C$9:I$18,3,FALSE),"Taxable")="Taxable",Calculations!B$404,0)+IF(IFERROR(VLOOKUP(C8,'Admin Input Sheet'!C$9:I$18,IF(Calculations!B406="FL",5,7),FALSE),"Store")="No County Tax",0,IF(IFERROR(VLOOKUP(C8,'Admin Input Sheet'!C$9:I$18,IF(Calculations!B406="FL",5,7),FALSE),"Store")="Customer",Calculations!B$410,Calculations!B$408)))) -> 0 | AY8: =K8 -> 0 | BA8: =IF(N8="No","Customer Declined",IF($I8>0,N8,"NO")) -> NO | BB8: =IF(AND(I8>0,N8="No"),"Customer Declined","No") -> No | BD8: =IF($I8>0,R8,"No") -> No | BF8: =IF($I8>0,T8,"No") -> No | BH8: =IF($I8>0,V8,"No") -> No | BJ8: =IF($I8>0,X8,"No") -> No
A9: Additional Product Sale | P9: =IF(N9="no",0,I9-K9) -> 0 | AA9: =IF(I9>0,IF($BD9<>"no",IF(C9<>0,UPPER(_xlfn.CONCAT(E9," ",C9)),""),""),"") | AB9: =IF($R9<>"no",IF(I9<>0,$I9,0),0) -> 0 | AC9: =IF($R9<>"no",IF($AX9<>0,$AX9,0),0) -> 0 | AD9: =IF($R9<>"no",IF($AY9<>0,$AY9,0),0) -> 0 | AE9: =IF(I9>0,IF($BF9<>"no",IF(C9<>0,UPPER(_xlfn.CONCAT(E9," ",C9)),""),""),"") | AF9: =IF($T9<>"no",IF(I9<>0,I9,0),0) -> 0 | AG9: =IF($T9<>"no",IF($AX9<>0,$AX9,0),0) -> 0 | AH9: =IF($T9<>"no",IF($AY9<>0,$AY9,0),0) -> 0 | AI9: =IF(I9>0,IF($BH9<>"no",IF(C9<>0,UPPER(_xlfn.CONCAT(E9," ",C9)),""),""),"") | AJ9: =IF($V9<>"no",IF($I9<>0,$I9,0),0) -> 0 | AK9: =IF($V9<>"no",IF($AX9<>0,$AX9,0),0) -> 0 | AL9: =IF($V9<>"no",IF($AY9<>0,$AY9,0),0) -> 0 | AM9: =IF(I9>0,IF($BJ9<>"no",IF(C9<>0,UPPER(_xlfn.CONCAT(E9," ",C9)),""),""),"") | AN9: =IF($X9<>"no",IF($I9<>0,$I9,0),0) -> 0 | AO9: =IF($X9<>"no",IF($AX9<>0,$AX9,0),0) -> 0 | AP9: =IF($X9<>"no",IF($AY9<>0,$AY9,0),0) -> 0 | AQ9: =IF(I9>0,IF($N9<>"no",IF(C9<>0,UPPER(_xlfn.CONCAT(E9," ",C9)),""),""),"") | AR9: =IF(N9<>"no",IF($I9<>0,$I9,0),0) -> 0 | AS9: =IF(N9<>"no",IF($AX9<>0,$AX9,0),0) -> 0 | AT9: =IF($N9<>"no",IF($AY9<>0,$AY9,0),0) -> 0 | AU9: =IF(I9>0,IF($N9="no",IF(C9<>0,UPPER(_xlfn.CONCAT(E9," ",C9)),""),""),"") | AW9: =_xlfn.CONCAT(C9) | AX9: =I9*(1+IF('Costing Sheet'!M8="Tax Exempt",0,IF(IFERROR(VLOOKUP(C9,'Admin Input Sheet'!C$9:I$18,3,FALSE),"Taxable")="Taxable",Calculations!B$404,0)+IF(IFERROR(VLOOKUP(C9,'Admin Input Sheet'!C$9:I$18,IF(Calculations!B407="FL",5,7),FALSE),"Store")="No County Tax",0,IF(IFERROR(VLOOKUP(C9,'Admin Input Sheet'!C$9:I$18,IF(Calculations!B407="FL",5,7),FALSE),"Store")="Customer",Calculations!B$410,Calculations!B$408)))) -> 0 | AY9: =K9 -> 0 | BA9: =IF(N9="No","Customer Declined",IF($I9>0,N9,"NO")) -> NO | BB9: =IF(AND(I9>0,N9="No"),"Customer Declined","No") -> No | BD9: =IF($I9>0,R9,"No") -> No | BF9: =IF($I9>0,T9,"No") -> No | BH9: =IF($I9>0,V9,"No") -> No | BJ9: =IF($I9>0,X9,"No") -> No
A10: Additional Product Sale | P10: =IF(N10="no",0,I10-K10) -> 0 | AA10: =IF(I10>0,IF($BD10<>"no",IF(C10<>0,UPPER(_xlfn.CONCAT(E10," ",C10)),""),""),"") | AB10: =IF($R10<>"no",IF(I10<>0,$I10,0),0) -> 0 | AC10: =IF($R10<>"no",IF($AX10<>0,$AX10,0),0) -> 0 | AD10: =IF($R10<>"no",IF($AY10<>0,$AY10,0),0) -> 0 | AE10: =IF(I10>0,IF($BF10<>"no",IF(C10<>0,UPPER(_xlfn.CONCAT(E10," ",C10)),""),""),"") | AF10: =IF($T10<>"no",IF(I10<>0,I10,0),0) -> 0 | AG10: =IF($T10<>"no",IF($AX10<>0,$AX10,0),0) -> 0 | AH10: =IF($T10<>"no",IF($AY10<>0,$AY10,0),0) -> 0 | AI10: =IF(I10>0,IF($BH10<>"no",IF(C10<>0,UPPER(_xlfn.CONCAT(E10," ",C10)),""),""),"") | AJ10: =IF($V10<>"no",IF($I10<>0,$I10,0),0) -> 0 | AK10: =IF($V10<>"no",IF($AX10<>0,$AX10,0),0) -> 0 | AL10: =IF($V10<>"no",IF($AY10<>0,$AY10,0),0) -> 0 | AM10: =IF(I10>0,IF($BJ10<>"no",IF(C10<>0,UPPER(_xlfn.CONCAT(E10," ",C10)),""),""),"") | AN10: =IF($X10<>"no",IF($I10<>0,$I10,0),0) -> 0 | AO10: =IF($X10<>"no",IF($AX10<>0,$AX10,0),0) -> 0 | AP10: =IF($X10<>"no",IF($AY10<>0,$AY10,0),0) -> 0 | AQ10: =IF(I10>0,IF($N10<>"no",IF(C10<>0,UPPER(_xlfn.CONCAT(E10," ",C10)),""),""),"") | AR10: =IF(N10<>"no",IF($I10<>0,$I10,0),0) -> 0 | AS10: =IF(N10<>"no",IF($AX10<>0,$AX10,0),0) -> 0 | AT10: =IF($N10<>"no",IF($AY10<>0,$AY10,0),0) -> 0 | AU10: =IF(I10>0,IF($N10="no",IF(C10<>0,UPPER(_xlfn.CONCAT(E10," ",C10)),""),""),"") | AW10: =_xlfn.CONCAT(C10) | AX10: =I10*(1+IF('Costing Sheet'!M9="Tax Exempt",0,IF(IFERROR(VLOOKUP(C10,'Admin Input Sheet'!C$9:I$18,3,FALSE),"Taxable")="Taxable",Calculations!B$404,0)+IF(IFERROR(VLOOKUP(C10,'Admin Input Sheet'!C$9:I$18,IF(Calculations!B408="FL",5,7),FALSE),"Store")="No County Tax",0,IF(IFERROR(VLOOKUP(C10,'Admin Input Sheet'!C$9:I$18,IF(Calculations!B408="FL",5,7),FALSE),"Store")="Customer",Calculations!B$410,Calculations!B$408)))) -> 0 | AY10: =K10 -> 0 | BA10: =IF(N10="No","Customer Declined",IF($I10>0,N10,"NO")) -> NO | BB10: =IF(AND(I10>0,N10="No"),"Customer Declined","No") -> No | BD10: =IF($I10>0,R10,"No") -> No | BF10: =IF($I10>0,T10,"No") -> No | BH10: =IF($I10>0,V10,"No") -> No | BJ10: =IF($I10>0,X10,"No") -> No
A11: Additional Product Sale | P11: =IF(N11="no",0,I11-K11) -> 0 | AA11: =IF(I11>0,IF($BD11<>"no",IF(C11<>0,UPPER(_xlfn.CONCAT(E11," ",C11)),""),""),"") | AB11: =IF($R11<>"no",IF(I11<>0,$I11,0),0) -> 0 | AC11: =IF($R11<>"no",IF($AX11<>0,$AX11,0),0) -> 0 | AD11: =IF($R11<>"no",IF($AY11<>0,$AY11,0),0) -> 0 | AE11: =IF(I11>0,IF($BF11<>"no",IF(C11<>0,UPPER(_xlfn.CONCAT(E11," ",C11)),""),""),"") | AF11: =IF($T11<>"no",IF(I11<>0,I11,0),0) -> 0 | AG11: =IF($T11<>"no",IF($AX11<>0,$AX11,0),0) -> 0 | AH11: =IF($T11<>"no",IF($AY11<>0,$AY11,0),0) -> 0 | AI11: =IF(I11>0,IF($BH11<>"no",IF(C11<>0,UPPER(_xlfn.CONCAT(E11," ",C11)),""),""),"") | AJ11: =IF($V11<>"no",IF($I11<>0,$I11,0),0) -> 0 | AK11: =IF($V11<>"no",IF($AX11<>0,$AX11,0),0) -> 0 | AL11: =IF($V11<>"no",IF($AY11<>0,$AY11,0),0) -> 0 | AM11: =IF(I11>0,IF($BJ11<>"no",IF(C11<>0,UPPER(_xlfn.CONCAT(E11," ",C11)),""),""),"") | AN11: =IF($X11<>"no",IF($I11<>0,$I11,0),0) -> 0 | AO11: =IF($X11<>"no",IF($AX11<>0,$AX11,0),0) -> 0 | AP11: =IF($X11<>"no",IF($AY11<>0,$AY11,0),0) -> 0 | AQ11: =IF(I11>0,IF($N11<>"no",IF(C11<>0,UPPER(_xlfn.CONCAT(E11," ",C11)),""),""),"") | AR11: =IF(N11<>"no",IF($I11<>0,$I11,0),0) -> 0 | AS11: =IF(N11<>"no",IF($AX11<>0,$AX11,0),0) -> 0 | AT11: =IF($N11<>"no",IF($AY11<>0,$AY11,0),0) -> 0 | AU11: =IF(I11>0,IF($N11="no",IF(C11<>0,UPPER(_xlfn.CONCAT(E11," ",C11)),""),""),"") | AW11: =_xlfn.CONCAT(C11) | AX11: =I11*(1+IF('Costing Sheet'!M10="Tax Exempt",0,IF(IFERROR(VLOOKUP(C11,'Admin Input Sheet'!C$9:I$18,3,FALSE),"Taxable")="Taxable",Calculations!B$404,0)+IF(IFERROR(VLOOKUP(C11,'Admin Input Sheet'!C$9:I$18,IF(Calculations!B409="FL",5,7),FALSE),"Store")="No County Tax",0,IF(IFERROR(VLOOKUP(C11,'Admin Input Sheet'!C$9:I$18,IF(Calculations!B409="FL",5,7),FALSE),"Store")="Customer",Calculations!B$410,Calculations!B$408)))) -> 0 | AY11: =K11 -> 0 | BA11: =IF(N11="No","Customer Declined",IF($I11>0,N11,"NO")) -> NO | BB11: =IF(AND(I11>0,N11="No"),"Customer Declined","No") -> No | BD11: =IF($I11>0,R11,"No") -> No | BF11: =IF($I11>0,T11,"No") -> No | BH11: =IF($I11>0,V11,"No") -> No | BJ11: =IF($I11>0,X11,"No") -> No
A12: Additional Product Sale | P12: =IF(N12="no",0,I12-K12) -> 0 | AA12: =IF(I12>0,IF($BD12<>"no",IF(C12<>0,UPPER(_xlfn.CONCAT(E12," ",C12)),""),""),"") | AB12: =IF($R12<>"no",IF(I12<>0,$I12,0),0) -> 0 | AC12: =IF($R12<>"no",IF($AX12<>0,$AX12,0),0) -> 0 | AD12: =IF($R12<>"no",IF($AY12<>0,$AY12,0),0) -> 0 | AE12: =IF(I12>0,IF($BF12<>"no",IF(C12<>0,UPPER(_xlfn.CONCAT(E12," ",C12)),""),""),"") | AF12: =IF($T12<>"no",IF(I12<>0,I12,0),0) -> 0 | AG12: =IF($T12<>"no",IF($AX12<>0,$AX12,0),0) -> 0 | AH12: =IF($T12<>"no",IF($AY12<>0,$AY12,0),0) -> 0 | AI12: =IF(I12>0,IF($BH12<>"no",IF(C12<>0,UPPER(_xlfn.CONCAT(E12," ",C12)),""),""),"") | AJ12: =IF($V12<>"no",IF($I12<>0,$I12,0),0) -> 0 | AK12: =IF($V12<>"no",IF($AX12<>0,$AX12,0),0) -> 0 | AL12: =IF($V12<>"no",IF($AY12<>0,$AY12,0),0) -> 0 | AM12: =IF(I12>0,IF($BJ12<>"no",IF(C12<>0,UPPER(_xlfn.CONCAT(E12," ",C12)),""),""),"") | AN12: =IF($X12<>"no",IF($I12<>0,$I12,0),0) -> 0 | AO12: =IF($X12<>"no",IF($AX12<>0,$AX12,0),0) -> 0 | AP12: =IF($X12<>"no",IF($AY12<>0,$AY12,0),0) -> 0 | AQ12: =IF(I12>0,IF($N12<>"no",IF(C12<>0,UPPER(_xlfn.CONCAT(E12," ",C12)),""),""),"") | AR12: =IF(N12<>"no",IF($I12<>0,$I12,0),0) -> 0 | AS12: =IF(N12<>"no",IF($AX12<>0,$AX12,0),0) -> 0 | AT12: =IF($N12<>"no",IF($AY12<>0,$AY12,0),0) -> 0 | AU12: =IF(I12>0,IF($N12="no",IF(C12<>0,UPPER(_xlfn.CONCAT(E12," ",C12)),""),""),"") | AW12: =_xlfn.CONCAT(C12) | AX12: =I12*(1+IF('Costing Sheet'!M11="Tax Exempt",0,IF(IFERROR(VLOOKUP(C12,'Admin Input Sheet'!C$9:I$18,3,FALSE),"Taxable")="Taxable",Calculations!B$404,0)+IF(IFERROR(VLOOKUP(C12,'Admin Input Sheet'!C$9:I$18,IF(Calculations!B410="FL",5,7),FALSE),"Store")="No County Tax",0,IF(IFERROR(VLOOKUP(C12,'Admin Input Sheet'!C$9:I$18,IF(Calculations!B410="FL",5,7),FALSE),"Store")="Customer",Calculations!B$410,Calculations!B$408)))) -> 0 | AY12: =K12 -> 0 | BA12: =IF(N12="No","Customer Declined",IF($I12>0,N12,"NO")) -> NO | BB12: =IF(AND(I12>0,N12="No"),"Customer Declined","No") -> No | BD12: =IF($I12>0,R12,"No") -> No | BF12: =IF($I12>0,T12,"No") -> No | BH12: =IF($I12>0,V12,"No") -> No | BJ12: =IF($I12>0,X12,"No") -> No
A13: Additional Product Sale | P13: =IF(N13="no",0,I13-K13) -> 0 | AA13: =IF(I13>0,IF($BD13<>"no",IF(C13<>0,UPPER(_xlfn.CONCAT(E13," ",C13)),""),""),"") | AB13: =IF($R13<>"no",IF(I13<>0,$I13,0),0) -> 0 | AC13: =IF($R13<>"no",IF($AX13<>0,$AX13,0),0) -> 0 | AD13: =IF($R13<>"no",IF($AY13<>0,$AY13,0),0) -> 0 | AE13: =IF(I13>0,IF($BF13<>"no",IF(C13<>0,UPPER(_xlfn.CONCAT(E13," ",C13)),""),""),"") | AF13: =IF($T13<>"no",IF(I13<>0,I13,0),0) -> 0 | AG13: =IF($T13<>"no",IF($AX13<>0,$AX13,0),0) -> 0 | AH13: =IF($T13<>"no",IF($AY13<>0,$AY13,0),0) -> 0 | AI13: =IF(I13>0,IF($BH13<>"no",IF(C13<>0,UPPER(_xlfn.CONCAT(E13," ",C13)),""),""),"") | AJ13: =IF($V13<>"no",IF($I13<>0,$I13,0),0) -> 0 | AK13: =IF($V13<>"no",IF($AX13<>0,$AX13,0),0) -> 0 | AL13: =IF($V13<>"no",IF($AY13<>0,$AY13,0),0) -> 0 | AM13: =IF(I13>0,IF($BJ13<>"no",IF(C13<>0,UPPER(_xlfn.CONCAT(E13," ",C13)),""),""),"") | AN13: =IF($X13<>"no",IF($I13<>0,$I13,0),0) -> 0 | AO13: =IF($X13<>"no",IF($AX13<>0,$AX13,0),0) -> 0 | AP13: =IF($X13<>"no",IF($AY13<>0,$AY13,0),0) -> 0 | AQ13: =IF(I13>0,IF($N13<>"no",IF(C13<>0,UPPER(_xlfn.CONCAT(E13," ",C13)),""),""),"") | AR13: =IF(N13<>"no",IF($I13<>0,$I13,0),0) -> 0 | AS13: =IF(N13<>"no",IF($AX13<>0,$AX13,0),0) -> 0 | AT13: =IF($N13<>"no",IF($AY13<>0,$AY13,0),0) -> 0 | AU13: =IF(I13>0,IF($N13="no",IF(C13<>0,UPPER(_xlfn.CONCAT(E13," ",C13)),""),""),"") | AW13: =_xlfn.CONCAT(C13) | AX13: =I13*(1+IF('Costing Sheet'!M12="Tax Exempt",0,IF(IFERROR(VLOOKUP(C13,'Admin Input Sheet'!C$9:I$18,3,FALSE),"Taxable")="Taxable",Calculations!B$404,0)+IF(IFERROR(VLOOKUP(C13,'Admin Input Sheet'!C$9:I$18,IF(Calculations!B411="FL",5,7),FALSE),"Store")="No County Tax",0,IF(IFERROR(VLOOKUP(C13,'Admin Input Sheet'!C$9:I$18,IF(Calculations!B411="FL",5,7),FALSE),"Store")="Customer",Calculations!B$410,Calculations!B$408)))) -> 0 | AY13: =K13 -> 0 | BA13: =IF(N13="No","Customer Declined",IF($I13>0,N13,"NO")) -> NO | BB13: =IF(AND(I13>0,N13="No"),"Customer Declined","No") -> No | BD13: =IF($I13>0,R13,"No") -> No | BF13: =IF($I13>0,T13,"No") -> No | BH13: =IF($I13>0,V13,"No") -> No | BJ13: =IF($I13>0,X13,"No") -> No
P14: PLAN PRICE | R14: =AB14 -> 0 | T14: =AF14 -> 0 | V14: =AJ14 -> 0 | X14: =AN14 -> 0 | AA14: totals | AB14: =SUM(AB4:AB13) -> 0 | AC14: =SUM(AC4:AC13) -> 0 | AD14: =SUM(AD4:AD13) -> 0 | AE14: totals | AF14: =SUM(AF4:AF13) -> 0 | AG14: =SUM(AG4:AG13) -> 0 | AH14: =SUM(AH4:AH13) -> 0 | AI14: totals | AJ14: =SUM(AJ4:AJ13) -> 0 | AK14: =SUM(AK4:AK13) -> 0 | AL14: =SUM(AL4:AL13) -> 0 | AM14: totals | AN14: =SUM(AN4:AN13) -> 0 | AO14: =SUM(AO4:AO13) -> 0 | AP14: =SUM(AP4:AP13) -> 0 | AQ14: totala | AR14: =SUM(AR4:AR13) -> 0 | AS14: =SUM(AS4:AS13) -> 0 | AT14: =SUM(AT4:AT13) -> 0 | AX14: =I14*(1+IF('Costing Sheet'!M13="Tax Exempt",0,IF(IFERROR(VLOOKUP(C14,'Admin Input Sheet'!C$9:I$18,3,FALSE),"Taxable")="Taxable",Calculations!B$404,0)+IF(IFERROR(VLOOKUP(C14,'Admin Input Sheet'!C$9:I$18,IF(Calculations!B412="FL",5,7),FALSE),"Store")="No County Tax",0,IF(IFERROR(VLOOKUP(C14,'Admin Input Sheet'!C$9:I$18,IF(Calculations!B412="FL",5,7),FALSE),"Store")="Customer",Calculations!B$410,Calculations!B$408)))) -> 0
A15: Include Kubota Insurance on Final Invocie and Payments | G15: Kubota Insurance Amount overide
A16: Agreed and Approved Finance Term
A17: Agreed and Approved Finance Rate
A18: Days to First Payment | I18: Name of Non Listed Finance Source
A19: Funding Lender | N19: DELAYED PAYMENT DATE
A20: Buy Rate | N20: Finance Spread | P20: =+Calculations!B609 -> 0 | BA20: {=IFERROR(INDEX('Finance Manager Input Sheet'!$AU$4:$AU$13, SMALL(IF('Finance Manager Input Sheet'!$BA$4:$BA$13="Customer Declined", ROW('Finance Manager Input Sheet'!$AU$4:$AU$13)-ROW('Finance Manager Input Sheet'!$AU$4)+1), ROW(C6))), "")} | BB20: {=IFERROR(INDEX('Finance Manager Input Sheet'!$AU$4:$AU$13, SMALL(IF('Finance Manager Input Sheet'!$BA$4:$BA$13="Customer Declined", ROW('Finance Manager Input Sheet'!$AU$4:$AU$13)-ROW('Finance Manager Input Sheet'!$AU$4)+1), ROW(D6))), "")}
A21: Rate Participation Percentage | BA21: {=IFERROR(INDEX('Finance Manager Input Sheet'!$AU$4:$AU$13, SMALL(IF('Finance Manager Input Sheet'!$BA$4:$BA$13="Customer Declined", ROW('Finance Manager Input Sheet'!$AU$4:$AU$13)-ROW('Finance Manager Input Sheet'!$AU$4)+1), ROW(C7))), "")} | BB21: {=IFERROR(INDEX('Finance Manager Input Sheet'!$AU$4:$AU$13, SMALL(IF('Finance Manager Input Sheet'!$BA$4:$BA$13="Customer Declined", ROW('Finance Manager Input Sheet'!$AU$4:$AU$13)-ROW('Finance Manager Input Sheet'!$AU$4)+1), ROW(D7))), "")}
A22: FLAT FEE DUE FROM LENDER | N22: Flat Fee From Lender | P22: =+C22 -> 0
A23: Cash in Lieu if not listed on incentives | E23: From What Party | I23: APPLICABLE TO WHICH UNIT | P23: =+C23 -> 0
A24: Cash in Lieu if not listed on incentives | E24: From What Party | I24: APPLICABLE TO WHICH UNIT | P24: =+C24 -> 0
A25: Cash in Lieu if not listed on incentives | E25: From What Party | I25: APPLICABLE TO WHICH UNIT | P25: =+C25 -> 0
A26: Rate Buydown cost
N27: Back End Margin | P27: =SUM(P4:P25) -> 0
A28: LOAN NUMBER

Sheet Admin Input Sheet
A3: Monthly KTC RATE 1 | C3: 0.0013
A4: Monthly KTC Rate 2 | C4: 0.002
A5: Monthly KTC Rate 3 | C5: 0
A6: Zero Cost Rate | C6: 0
C8: Name | E8: Taxable | G8: Florida County Tax Level | I8: Georgia County Tax Level
A9: Product 1
A10: Product 2
A11: Product 3
A12: Product 4
A13: Product 5
A14: Product 6
A15: Product 7
A16: Product 8
A17: Product 9
A18: Product 10
C20: Amount | E20: Cutoff | G20: Aggregate or Individual
A21: Lowest cutoff Dealer fee | C21: 0 | E21: 3999 | G21: Individual
A22: Second lowest cutoff dlr fee | C22: 299 | E22: 9999 | G22: Aggregate
A23: third lowest cutoff dealer fee | C23: 649 | E23: 39999 | G23: Aggregate
A24: fourth lowest cutoff dealer fee | C24: 849 | E24: 79999 | G24: Aggregate
A25: fifth lowest cutof dealer fee | C25: 849 | E25: 99999 | G25: Aggregate
A26: highest level of dealer fee | C26: 1149 | G26: Aggregate
E27: State Tax Level | G27: County Tax Level
A28: Florida Battery Fee per unit | C28: 1.5 | E28: Customer | G28: No County Tax
A29: Georgia Battery Fee per unit | C29: 0 | E29: No State Tax | G29: No County Tax
A30: Florida Tire Tax per unit | C30: 1 | E30: Customer | G30: No County Tax
A31: Georgia Tire Tax per Unit | C31: 0 | E31: No State Tax | G31: No County Tax
A33: Title of Document Fee | C33: Dealer Fee
C34: State Taxable | E34: Florida County Tax Level | G34: Georgia County Tax Level
A35: Freight Charge | C35: Taxable | E35: Customer | G35: Customer
A36: Prep Charge | C36: Taxable | E36: Customer | G36: Customer
A37: DMV Charges | C37: Non Taxable | E37: No County Tax | G37: No County Tax
A38: Title Fees | C38: Non Taxable | E38: No County Tax | G38: No County Tax
A39: Tag Fees | C39: Non Taxable | E39: No County Tax | G39: No County Tax
A41: Florida State Sales Tax Rate | C41: 0.06
A42: Georgia State Sales Tax Rate | C42: 0.04
A43: Florida Per Item Sales Tax Cap | C43: 5000
A44: Georgia Per Item Sales tax Cap | C44: 1000000

Sheet Rates for Quote
A2: Rates For Matrix
C3: Regular Equipment Rate | D3: Mower And UTV Rate | E3: Prime Rate | F3: Overide Rate
A4: Term 1
A6: Term 2
A8: Term 3
A10: Down Payment 1
A11: Down Payment 2
A12: Down Payment 3

Sheet Quote
B2: CAIRO, GA | CHIEFLAND,FL. | DELAND, FL. | K2: CRYSTAL | Q2: =+Calculations!$B$568
B4: HASTINGS, FL | HOMOSASSA, FL | JACKSONVILLE, FL | LECANTO, FL | Q4: =+Calculations!$B$569
Q5: =Calculations!B570
B6: LEESBURG, FL. | LIVE OAK, FL. | MADISON, FL | K6: TRACTOR & EQUIPMENT
B8: MIAMI, FL. | PALATKA, FL. | PANAMA CITY, FL | OCALA, FL
B10: SPRING HILL, FL. | STARKE, FL. | TALLAHASSEE, FL | K10: =+Calculations!B572 -> CRYSTALTRACTOR.COM | Q10: =Calculations!B571
B11: CUSTOMER:
C12: =IF('Customer Input Screen'!I10<>"",UPPER('Customer Input Screen'!I10),"") | L12: CUSTOMER CELL | O12: =+'Customer Input Screen'!I22 | Q12: QUOTE NUMBER | S12: =+'Sales Input Sheet'!C11 -> 0
C13: =IF(Calculations!B3<>"",UPPER(Calculations!B3),"") | L13: CUSTOMER WORK | O13: =+'Customer Input Screen'!I23 | Q13: QUOTE DATE | S13: =+'Costing Sheet'!C15 -> 0
C15: =IF('Customer Input Screen'!I14<>"",UPPER('Customer Input Screen'!I14),"") | L15: CUSTOMER HOME | O15: =+'Customer Input Screen'!I24 | Q15: SALES PERSON | S15: =IF('Sales Input Sheet'!C15<>"",UPPER('Sales Input Sheet'!C15),"")
C16: =IF('Customer Input Screen'!I15<>"",UPPER('Customer Input Screen'!I15),"") | L16: =+Calculations!$B$602 | Q16: =UPPER('Costing Sheet'!C17) | S16: =UPPER('Costing Sheet'!E17)
C17: =+Calculations!$B$601 | L17: PURCHASE ORDER NO. | O17: =UPPER('Costing Sheet'!U19)
B19: Customer hereby orders the following described machinery and equipment from Crystal Tractor, LLC, Crystal Equipment, LLC or Crystal Motorsports, LLC. Upon acceptance by Seller and Customer, this order becomes a agreement to endeavor to conclude the purchase and sale of goods upon the terms and conditions set forth herein and on the reverse of this order.
Q21: DEALER SUGGESTED PRICE | S21: DISCOUNT | U21: NET SELLING PRICE
C22: STOCK NUMBER | I22: MAKE | L22: MODEL | O22: SERIAL NUMBER
C23: =Calculations!B451 | I23: =Calculations!B6 | L23: =Calculations!B7 | O23: =Calculations!B8 | Q23: =+'Costing Sheet'!I$22 -> 0 | S23: =-'Costing Sheet'!K$22 -> 0 | U23: =+Calculations!B$526 -> 0
J24: =Calculations!B9
J25: =+Calculations!B12
C27: =Calculations!B452 | I27: =Calculations!B18 | L27: =Calculations!B19 | O27: =Calculations!B20 | Q27: =+'Costing Sheet'!I$23 -> 0 | S27: =-'Costing Sheet'!K$23 -> 0 | U27: =+Calculations!B$527 -> 0
J28: =Calculations!B21
J29: =+Calculations!B24
C31: =Calculations!B453 | I31: =Calculations!B30 | L31: =Calculations!B31 | O31: =Calculations!B32 | Q31: =+'Costing Sheet'!I$24 -> 0 | S31: =-'Costing Sheet'!K$24 -> 0 | U31: =+Calculations!B$528 -> 0
J32: =Calculations!B33
J33: =+Calculations!B36
C35: =Calculations!B454 | I35: =Calculations!B42 | L35: =Calculations!B43 | O35: =Calculations!B44 | Q35: =+'Costing Sheet'!I$25 -> 0 | S35: =-'Costing Sheet'!K$25 -> 0 | U35: =+Calculations!B$529 -> 0
J36: =Calculations!B45
J37: =+Calculations!B48
C39: =Calculations!B455 | I39: =Calculations!B54 | L39: =Calculations!B55 | O39: =Calculations!B56 | Q39: =+'Costing Sheet'!I$26 -> 0 | S39: =-'Costing Sheet'!K$26 -> 0 | U39: =+Calculations!B$530 -> 0
J40: =Calculations!B57
J41: =+Calculations!B60
C43: =Calculations!B456 | I43: =Calculations!B66 | L43: =Calculations!B67 | O43: =Calculations!B68 | Q43: =+'Costing Sheet'!I$27 -> 0 | S43: =-'Costing Sheet'!K$27 -> 0 | U43: =+Calculations!B$531 -> 0
J44: =Calculations!B69
J45: =+Calculations!B72
C47: =Calculations!B457 | I47: =Calculations!B78 | L47: =Calculations!B79 | O47: =Calculations!B80 | Q47: =+'Costing Sheet'!I$28 -> 0 | S47: =-'Costing Sheet'!K$28 -> 0 | U47: =+Calculations!B$532 -> 0
J48: =Calculations!B81
J49: =+Calculations!B84
C51: =Calculations!B458 | I51: =Calculations!B90 | L51: =Calculations!B91 | O51: =Calculations!B92 | Q51: =+'Costing Sheet'!I$29 -> 0 | S51: =-'Costing Sheet'!K$29 -> 0 | U51: =+Calculations!B$533 -> 0
J52: =Calculations!B93
J53: =+Calculations!B96
C55: =Calculations!B459 | I55: =Calculations!B102 | L55: =Calculations!B103 | O55: =Calculations!B104 | Q55: =+'Costing Sheet'!I$30 -> 0 | S55: =-'Costing Sheet'!K$30 -> 0 | U55: =+Calculations!B$534 -> 0
...

Sheet Additional Items
I2: =+Calculations!$B$568
I4: =+Calculations!$B$569
I5: =Calculations!B570
I8: =Calculations!B571
Q9: QUOTE NUMBER | S9: =+'Sales Input Sheet'!C11 -> 0
Q10: INVOICE NUMBER | S10: =+'Costing Sheet'!$C$13 -> 0
B11: CUSTOMER: | Q11: INVOICE DATE | S11: ='Costing Sheet'!$C$11 -> 0
C13: =IF('Customer Input Screen'!I10<>"",UPPER('Customer Input Screen'!I10),"") | Q13: Sales Person | S13: =IF('Sales Input Sheet'!C15<>"",UPPER('Sales Input Sheet'!C15),"")
C14: =IF(Calculations!B3<>"",UPPER(Calculations!B3),"") | Q14: Customer Cell | R14: =+'Customer Input Screen'!I22
C15: =IF('Customer Input Screen'!I14<>"",UPPER('Customer Input Screen'!I14),"") | Q15: Customer Work | R15: =+'Customer Input Screen'!I23
Q16: DEALER SUGGESTED PRICE | S16: DISCOUNT | U16: NET SELLING PRICE
C17: STOCK NUMBER | F17: MAKE | I17: MODEL | L17: SERIAL NUMBER
F18: =+Calculations!B461 -> 0 | I18: =Calculations!B466 | L18: =Calculations!B471 | Q18: =+'Costing Sheet'!I$34 -> 0 | S18: =-'Costing Sheet'!K$34 -> 0 | U18: =+Calculations!B$536 -> 0
J20: =UPPER(Calculations!B125)
F22: =+Calculations!B462 -> 0 | I22: =Calculations!B467 | L22: =Calculations!B472 | Q22: =+'Costing Sheet'!I$35 -> 0 | S22: =-'Costing Sheet'!K$35 -> 0 | U22: =+Calculations!B$537 -> 0
J24: =UPPER(Calculations!B129)
F26: =+Calculations!B463 -> 0 | I26: =Calculations!B468 | L26: =Calculations!B473 | Q26: =+'Costing Sheet'!I$36 -> 0 | S26: =-'Costing Sheet'!K$36 -> 0 | U26: =+Calculations!B$538 -> 0
J28: =UPPER(Calculations!B133)
F30: =+Calculations!B464 -> 0 | I30: =Calculations!B469 | L30: =Calculations!B474 | Q30: =+'Costing Sheet'!I$37 -> 0 | S30: =-'Costing Sheet'!K$37 -> 0 | U30: =+Calculations!B$539 -> 0
J32: =UPPER(Calculations!B137)
F34: =+Calculations!B465 -> 0 | I34: =Calculations!B470 | L34: =Calculations!B475 | Q34: =+'Costing Sheet'!I$38 -> 0 | S34: =-'Costing Sheet'!K$38 -> 0 | U34: =+Calculations!B$540 -> 0
J36: =UPPER(Calculations!B141)
C38: QUANTITY | F38: MAKE | I38: MODEL | L38: PART NUMBER | Q38: PER UNIT PRICE | S38: PER UNIT DISCOUNT | U38: EXTENDED VALUE
C40: =+Calculations!B476 | F40: =+Calculations!B491 | I40: =+Calculations!B481 | L40: =+Calculations!B486 | Q40: =+'Costing Sheet'!I$42 -> 0 | S40: =-'Costing Sheet'!K$42 -> 0 | U40: =+Calculations!B$541 -> 0
J41: =Calculations!B145
C43: =+Calculations!B477 | F43: =+Calculations!B492 | I43: =+Calculations!B482 | L43: =+Calculations!B487 | Q43: =+'Costing Sheet'!I$43 -> 0 | S43: =-'Costing Sheet'!K$43 -> 0 | U43: =+Calculations!B$542 -> 0
J44: =Calculations!B153
C46: =+Calculations!B478 | F46: =+Calculations!B493 | I46: =+Calculations!B483 | L46: =+Calculations!B488 | Q46: =+'Costing Sheet'!I$44 -> 0 | S46: =-'Costing Sheet'!K$44 -> 0 | U46: =+Calculations!B$543 -> 0
J47: =Calculations!B161
C49: =+Calculations!B479 | F49: =+Calculations!B494 | I49: =+Calculations!B484 | L49: =+Calculations!B489 | Q49: =+'Costing Sheet'!I$45 -> 0 | S49: =-'Costing Sheet'!K$45 -> 0 | U49: =+Calculations!B$544 -> 0
J50: =Calculations!B169
C52: =+Calculations!B480 | F52: =+Calculations!B495 | I52: =+Calculations!B485 | L52: =+Calculations!B490 | Q52: =+'Costing Sheet'!I$46 -> 0 | S52: =-'Costing Sheet'!K$46 -> 0 | U52: =+Calculations!B$545 -> 0
J53: =Calculations!B177

Sheet Work a Quote
D1: PRIOR PENCIL | F1: Revised Loan Terms to achieve Desired Payment
B2: APR | F2: =IF(D9="",0,IF(D11="Rate",Calculations!B606,D2)) -> 0
B3: Month Term | F3: =IF(D9="",0,IF(D11="Term",Calculations!B607,D3)) -> 0
B4: Down Payment | F4: =IF(D9="",0,IF(D11="down payment",Calculations!B608,D4)) -> 0
B5: Payment at Prior Pencil | D5: =IF(AND($D$2<>"",$D$3<>""),-PMT($D$2/12,$D$3,(Calculations!D427+Calculations!B435)-$D$4),0) -> 0
B9: Desired Payment
B11: Where to roll payment
F15: New Terms
B16: APR
B17: Month Term
B18: Down Payment
D22: Original Matrix | F22: Revised Amount | H22: Change In Profit
B23: Original Net Equipment Price | D23: =+Quote!L99 -> 0 | H23: =IF(F23=0,0,F23-D23) -> 0
B24: Original Trade ALLOWANCE | D24: =+Quote!L100 -> 0 | H24: =IF(F24=0,0,-F24+D24) -> 0
B25: INCLUDE ADDITONAL EQUIPMENT AT NO COST TO CUSTOMER | D25: 0 | H25: =IF(F25=0,0,-F25) -> 0
B26: Incentives | D26: =Calculations!B324 -> 0 | F26: 0 | H26: =IF(F26=0,0,F26-D26) -> 0
B28: Include Kubota Insurance in Revised Quote | D28: ='Costing Sheet'!M17 -> 0
B30: Payment at Prior Pencil | D30: =D5 -> 0 | F30: New Payment | H30: =IF(AND(F16<>"",F17<>""),-PMT(F16/12,F17,(-F18+Calculations!D435+Calculations!D428)),0) -> 0
B33: Front End Profit | D33: =+Recap!P97 -> 0 | F33: Revised Front End Profit | H33: =D33+SUM(H23:H26) -> 0

Sheet Agreed Terms to Finance
B2: CAIRO, GA | CHIEFLAND,FL. | DELAND, FL. | K2: CRYSTAL | Q2: =+Calculations!$B$568
B4: HASTINGS, FL | HOMOSASSA, FL | JACKSONVILLE, FL | LECANTO, FL | Q4: =+Calculations!$B$569
Q5: =Calculations!B570
B6: LEESBURG, FL. | LIVE OAK, FL. | MADISON, FL | K6: TRACTOR & EQUIPMENT
B8: MIAMI, FL. | PALATKA, FL. | PANAMA CITY, FL | OCALA, FL
B10: SPRING HILL, FL. | STARKE, FL. | TALLAHASSEE, FL | K10: =+Calculations!B572 -> CRYSTALTRACTOR.COM | Q10: =Calculations!B571
B11: CUSTOMER: | Q11: QUOTE NUMBER | S11: =+'Sales Input Sheet'!C11 -> 0
C12: =IF('Customer Input Screen'!I10<>"",UPPER('Customer Input Screen'!I10),"") | L12: CUSTOMER CELL | O12: =+'Customer Input Screen'!I22 | Q12: INVOICE NUMBER | S12: =+'Costing Sheet'!$C$13 -> 0
C13: =IF(Calculations!B3<>"",UPPER(Calculations!B3),"") | L13: CUSTOMER WORK | O13: =+'Customer Input Screen'!I23 | Q13: QUOTE DATE | S13: =+'Sales Input Sheet'!C13 -> 0
C15: =IF('Customer Input Screen'!I14<>"",UPPER('Customer Input Screen'!I14),"") | L15: CUSTOMER HOME | O15: =+'Customer Input Screen'!I24 | Q15: SALES PERSON | S15: =IF('Sales Input Sheet'!C15<>"",UPPER('Sales Input Sheet'!C15),"")
C16: =IF('Customer Input Screen'!I15<>"",UPPER('Customer Input Screen'!I15),"") | L16: =+Calculations!$B$602
C17: =+Calculations!$B$601 | L17: PURCHASE ORDER NO. | O17: =UPPER('Costing Sheet'!U19)
B19: Customer hereby orders the following described machinery and equipment from Crystal Tractor, LLC, Crystal Equipment, LLC or Crystal Motorsports, LLC. Upon acceptance by Seller and Customer, this order becomes a agreement to endeavor to conclude the purchase and sale of goods upon the terms and conditions set forth herein and on the reverse of this order.
Q21: DEALER SUGGESTED PRICE | S21: DISCOUNT | U21: NET SELLING PRICE
C22: STOCK NUMBER | I22: MAKE | L22: MODEL | O22: SERIAL NUMBER
C23: =Calculations!B451 | I23: =Calculations!B6 | L23: =Calculations!B7 | O23: =Calculations!B8 | Q23: =+'Costing Sheet'!I$22 -> 0 | S23: =-'Costing Sheet'!K$22 -> 0 | U23: =+Calculations!B$526 -> 0
