Workbook

Sheet Plan Summary
A3: Equipment Class | C3: RTV
A5: Plan Hours | C5: 300 | D5: Hours
A7: Service At Shop or In Field | C7: Service In Shop
J8: Total Hours | K8: Total Labor
A9: Plan Term | C9: 60 | D9: Months | H9: Labor Rate | I9: =IF(C7="Service in Field",'Plan Set Up'!E2,'Plan Set Up'!E1) -> 120 | J9: =SUM(K13:K132) -> 11.55 | K9: =IF(AND(I9<>"",J9<>""),+J9*I9,"") -> 1386
A11: Total Cost For Plan | C11: =IFERROR(VLOOKUP(C3,'Total Cost for Plan'!A4:BQ34,69,0),0)+180 -> 2238.34 | F11: Reimbursement | G11: Interval | H11: Occurence in Plan | I11: Total for Line Item | J11: Hours Per item | K11: Total Hours
A13: =_xlfn.TEXTJOIN(", ",TRUE,'Scheduled Intervals'!B43:B92) -> 50 hours Perform Oil and Filter Change, Change HST Oil Filter , Grease Machine at required lubrication fittings, Conduct Multi Point Inpection and make minor adjustments, Change Hydraulic suction return filter | F13: =SUM('Scheduled Intervals'!C43:C61) -> 351.31 | G13: ='Scheduled Intervals'!B37 -> 50 | H13: 1 | I13: =F13*H13 -> 351.31 | J13: =SUM('Scheduled Intervals'!D43:D61) -> 1.65 | K13: =IF(AND(H13<>"",J13<>""),+J13*H13,"") -> 1.65
A17: =CONCATENATE("Includes ",C7) -> Includes Service In Shop
A18: {=_xlfn.SORTBY('Scheduled Intervals'!F43:F94,'Scheduled Intervals'!G43:G94)} -> Perform Annual Oil and Filter Change | F18: {=_xlfn.SORTBY('Scheduled Intervals'!H43:H94,'Scheduled Intervals'!G43:G94)} -> 89.63 | G18: {=_xlfn.SORTBY('Scheduled Intervals'!G43:G94,'Scheduled Intervals'!G43:G94)} -> 1 | H18: {=_xlfn.SORTBY('Scheduled Intervals'!I43:I94,'Scheduled Intervals'!G43:G94)} -> 5 | I18: =IF(F18<>"",(F18*H18),"") -> 448.15 | J18: {=_xlfn.SORTBY('Scheduled Intervals'!J43:J94,'Scheduled Intervals'!G43:G94)} -> 0.4 | K18: =IF(AND(H18<>"",J18<>""),+J18*H18,"") -> 2
A19: Annually Grease Machine at Assorted Lubrication Points | F19: 23.07 | G19: 1 | H19: 5 | I19: =IF(F19<>"",(F19*H19),"") -> 115.35 | J19: 0.1 | K19: =IF(AND(H19<>"",J19<>""),+J19*H19,"") -> 0.5
A20: Conduct Annual Multi Point Inpection and Make Minor Adjustments | F20: 126 | G20: 1 | H20: 5 | I20: =IF(F20<>"",(F20*H20),"") -> 630 | J20: 1.05 | K20: =IF(AND(H20<>"",J20<>""),+J20*H20,"") -> 5.25
A21: Every 200 hours - Perform Oil and Filter Change | F21: 89.63 | G21: 200 | H21: 1 | I21: =IF(F21<>"",(F21*H21),"") -> 89.63 | J21: 0.4 | K21: =IF(AND(H21<>"",J21<>""),+J21*H21,"") -> 0.4
A22: Every 200 hours - Drain Water from Fuel Tank | F22: 12 | G22: 200 | H22: 1 | I22: =IF(F22<>"",(F22*H22),"") -> 12 | J22: 0.1 | K22: =IF(AND(H22<>"",J22<>""),+J22*H22,"") -> 0.1
A23: Every 200 hours - Replace Transmission Oil Filters | F23: 51.07 | G23: 200 | H23: 1 | I23: =IF(F23<>"",(F23*H23),"") -> 51.07 | J23: 0.2 | K23: =IF(AND(H23<>"",J23<>""),+J23*H23,"") -> 0.2
A24: Every 200 hours - Change Hydraulic Oil Filter | F24: 76.69 | G24: 200 | H24: 1 | I24: =IF(F24<>"",(F24*H24),"") -> 76.69 | J24: 0.2 | K24: =IF(AND(H24<>"",J24<>""),+J24*H24,"") -> 0.2
A25: Every 200 hours - Change Suction Elements and Hydraulic Fluid | F25: 231.1 | G25: 200 | H25: 1 | I25: =IF(F25<>"",(F25*H25),"") -> 231.1 | J25: 0.9 | K25: =IF(AND(H25<>"",J25<>""),+J25*H25,"") -> 0.9
A26: Every 200 hours - Grease Machine at Assorted Lubrication Points | F26: 23.07 | G26: 200 | H26: 1 | I26: =IF(F26<>"",(F26*H26),"") -> 23.07 | J26: 0.1 | K26: =IF(AND(H26<>"",J26<>""),+J26*H26,"") -> 0.1
A27: Every 200 hours - Conduct Multi Point Inpection and Make Minor Adjustments | F27: 30 | G27: 200 | H27: 1 | I27: =IF(F27<>"",(F27*H27),"") -> 30 | J27: 0.25 | K27: =IF(AND(H27<>"",J27<>""),+J27*H27,"") -> 0.25
I28: =IF(F28<>"",(F28*H28),"") | K28: =IF(AND(H28<>"",J28<>""),+J28*H28,"")
I29: =IF(F29<>"",(F29*H29),"") | K29: =IF(AND(H29<>"",J29<>""),+J29*H29,"")
I30: =IF(F30<>"",(F30*H30),"") | K30: =IF(AND(H30<>"",J30<>""),+J30*H30,"")
I31: =IF(F31<>"",(F31*H31),"") | K31: =IF(AND(H31<>"",J31<>""),+J31*H31,"")
I32: =IF(F32<>"",(F32*H32),"") | K32: =IF(AND(H32<>"",J32<>""),+J32*H32,"")
I33: =IF(F33<>"",(F33*H33),"") | K33: =IF(AND(H33<>"",J33<>""),+J33*H33,"")
I34: =IF(F34<>"",(F34*H34),"") | K34: =IF(AND(H34<>"",J34<>""),+J34*H34,"")
I35: =IF(F35<>"",(F35*H35),"") | K35: =IF(AND(H35<>"",J35<>""),+J35*H35,"")
I36: =IF(F36<>"",(F36*H36),"") | K36: =IF(AND(H36<>"",J36<>""),+J36*H36,"")
I37: =IF(F37<>"",(F37*H37),"") | K37: =IF(AND(H37<>"",J37<>""),+J37*H37,"")
I38: =IF(F38<>"",(F38*H38),"") | K38: =IF(AND(H38<>"",J38<>""),+J38*H38,"")
I39: =IF(F39<>"",(F39*H39),"") | K39: =IF(AND(H39<>"",J39<>""),+J39*H39,"")
... I69: =IF(F69<>"",(F69*H69),"") | K69: =IF(AND(H69<>"",J69<>""),+J69*H69,"")

Sheet Interval Summary
A3: Equipment Class | C3: Skid Steer
A5: Interval | C5: 500 | D5: Hours
A7: Plan Includes Service At Shop or In Field | C7: Service In Shop
A9: Remibursement Rate | C9: =IF(C7="service in Shop",'Plan Set Up'!E1,'Plan Set Up'!E2) -> 120
A11: Services Included at Interval
A13: =_xlfn.TEXTJOIN(", ",TRUE,'Included @ Interval'!B39:B126) -> Perform Oil and Filter Change, Drain Water from Fuel Tank, Change fuel Filter Element, Change Hydraulic Oil Filter, Change or Clean Hydraulic Breather Element , Change or Clean Hydraulic return Filter , Change or Clean Cabin Air Filter, Grease Machine at Assorted Lubrication Points, Replace Air Cleaner element, Conduct Multi Point Inpection and Make Minor Adjustments
A18: Labor Hours Reimbursed | C18: =IFERROR(VLOOKUP($C$3,'Interval Reimb'!A$4:BR431,70,0),0) -> 3.75
A21: Remibursement for Service | C21: =IFERROR(VLOOKUP($C$3,'Interval Reimb'!A$4:BQ434,69,0),0) -> 1035.58

Sheet Scheduled Intervals
B1: First Service | Q1: One Time | U1: Included Maintenance Interval
A2: Category | B2: Perform Oil and Filter Change | C2: Clean Water seperator | D2: Drain Water from Fuel Tank | E2: Perform Transmission Filter and Fluid Service | F2: Change HST Oil Filter | G2: Change Hydraulic Fluid | H2: Grease Machine at required lubrication fittings | I2: Conduct Multi Point Inpection and make minor adjustments | J2: Perform Track Tension Adjustment | K2: Change fuel filter element | L2: Change final drive fluid | M2: Change hydraulic return filter | N2: Change final drive fluid | O2: Change final drive fluid | P2: Change Hydraulic suction return filter | Q2: Change Hydraulic Oil Filter and Oil | R2: Final Drive or Hydrostatic Oil Change | S2: Change Transmission Fluid and filters | T2: Change Hydraulic fluid | U2: Perform Oil and Filter Change | V2: Change Oil Seperator Element | W2: Clean Water seperator | X2: Replace Water Seperator Element | Y2: Drain Water from Fuel Tank | Z2: Change fuel Filter Element | AA2: Change Fuel Pump Filter and/or PCV Element | AB2: Perform Transmission Fluid and Tank Service | AC2: Replace Transmission Oil Filters | AE2: Change Hydraulic Oil Filter | AF2: Change or Clean Hydraulic Breather Element | AG2: Change or Clean Hydraulic return Filter | AH2: Change Hydraulic Pilot Filters and O-Ring | AI2: Change Suction Elements and Hydraulic Fluid | AJ2: Change Drive Oil - Front and Rear or Hydrostatic | AK2: Change Drive Oil Rear | AL2: Change Drive Oil Front | AM2: Change Gear Box Oil and Filter | AN2: Change Gear Box Seals | AO2: Grease Crank Shaft | AP2: Clean AC Condensor | AQ2: Clean Cabin Air Filter | AR2: Change Breather Foam | AS2: Change or Clean Cabin Air Filter | AT2: Grease Machine at Assorted Lubrication Points | AU2: Lubricate and Oil Throttle Cable | AV2: Adjust Track Tension | AW2: Check and Adjust Valve Clearance | AY2: Adjust Electonic Clutch | AZ2: Replace Fan/ Drive Belt | BA2: Replace or Replenish Power Steering Fluid | BB2: Replace Air Cleaner element | BC2: Replace Inner Air Filter | BD2: Replace Spark Plugs | BE2: Check End Play of Center Shaft and Make minor Adjustment | BF2: Check PCV and EGR Valves and Check Fuel Injectors | BG2: Check DEF Injector Tips and Line | BH2: Perform Coolant System Flush | BI2: Inspect and Sharpen Blades | BJ2: Conduct Multi Point Inpection and Make Minor Adjustments | BK2: Change DEF Suction and Pump Filters | BL2: Perform Brake Fluid Service | BM2: Change Swing Drive Oil | BN2: Perform Annual Oil and Filter Change | BO2: Annually Grease Machine at Assorted Lubrication Points | BP2: Conduct Annual Multi Point Inpection and Make Minor Adjustments | BQ2: Minimum Annual Hours
B3: Parts and Labor | C3: Labor Only | D3: Labor Only | E3: Parts and Labor | F3: Parts and Labor | G3: Parts and Labor | H3: Parts and Labor | I3: Labor Only | J3: Labor Only | K3: Parts and Labor | L3: Parts and Labor | M3: Parts and Labor | N3: Parts and Labor | O3: Parts and Labor | P3: Parts and Labor | Q3: Parts and Labor | R3: Parts and Labor | S3: Parts and Labor | T3: Parts and Labor | U3: Parts and Labor | V3: Parts and Labor | W3: Labor Only | X3: Parts and Labor | Y3: Labor Only | Z3: Parts and Labor | AA3: Parts and Labor | AB3: Parts and Labor | AC3: Parts and Labor | AD3: Parts and Labor | AE3: Parts and Labor | AF3: Parts and Labor | AG3: Parts and Labor | AH3: Parts and Labor | AI3: Parts and Labor | AJ3: Parts and Labor | AK3: Parts and Labor | AL3: Parts and Labor | AM3: Parts and Labor | AN3: Parts and Labor | AO3: Parts and Labor | AP3: Labor Only | AQ3: Labor Only | AR3: Parts and Labor | AS3: Parts and Labor | AT3: Parts and Labor | AU3: Parts and Labor | AV3: Labor Only | AW3: Parts and Labor | AX3: Parts and Labor | AY3: Labor Only | AZ3: Parts and Labor | BA3: Parts and Labor | BB3: Parts and Labor | BC3: Parts and Labor | BD3: Parts and Labor | BE3: Labor Only | BF3: Labor Only | BG3: Labor Only | BH3: Parts and Labor | BI3: Labor Only | BJ3: Labor Only | BK3: Parts and Labor | BL3: Parts and Labor | BM3: Parts and Labor | BN3: Parts and Labor | BO3: Parts and Labor | BP3: Labor Only
A4: RTV | B4: 50 | F4: 50 | H4: 50 | I4: 50 | P4: 50 | U4: 200 | Y4: 200 | Z4: 400 | AB4: 400 | AC4: 200 | AE4: 200 | AI4: 200 | AL4: 400 | AT4: 200 | AW4: 800 | BB4: 1000 | BC4: 1000 | BD4: 500 | BH4: 2000 | BJ4: 200 | BN4: Annual | BO4: Annual | BP4: Annual | BQ4: 200
A5: Zero Turn Gas | B5: 8 | H5: 50 | I5: 50 | S5: 100 | U5: 100 | Z5: 100 | AB5: 400 | AC5: 400 | AT5: 100 | BB5: 100 | BD5: 500 | BH5: 100 | BI5: 100 | BJ5: 100 | BN5: Annual | BO5: Annual | BP5: Annual | BQ5: 100
A6: Zero Turn Diesel | B6: 50 | F6: 50 | H6: 50 | I6: 50 | U6: 200 | X6: 400 | Z6: 400 | AB6: 400 | AC6: 200 | AE6: 400 | AT6: 200 | AW6: 800 | BB6: 1000 | BC6: 1000 | BH6: 2000 | BI6: 200 | BJ6: 200 | BN6: Annual | BO6: Annual | BP6: Annual | BQ6: 200
A7: Compact L series | B7: 50 | F7: 50 | H7: 50 | I7: 50 | M7: 50 | U7: 200 | Z7: 400 | AB7: 400 | AC7: 200 | AE7: 400 | AL7: 800 | AP7: 200 | AQ7: 200 | AT7: 200 | AW7: 800 | BB7: 1000 | BH7: 2000 | BJ7: 200 | BN7: Annual | BO7: Annual | BP7: Annual | BQ7: 200
A8: Utility under 75 MX&M | B8: 50 | F8: 50 | H8: 50 | I8: 50 | U8: 400 | V8: 1200 | W8: 400 | Y8: 400 | Z8: 400 | AB8: 400 | AE8: 400 | AL8: 800 | AP8: 800 | AQ8: 800 | AS8: 800 | AT8: 400 | BB8: 800 | BC8: 800 | BF8: 1200 | BG8: 1200 | BH8: 2000 | BJ8: 400 | BN8: Annual | BO8: Annual | BP8: Annual | BQ8: 400
A9: Utility over 75 M4 class | B9: 50 | H9: 50 | I9: 50 | U9: 500 | V9: 1500 | W9: 500 | Y9: 500 | Z9: 500 | AB9: 1000 | AE9: 500 | AJ9: 1000 | AS9: 1000 | AT9: 500 | AW9: 1000 | BB9: 1000 | BF9: 1500 | BG9: 1500 | BH9: 2000 | BJ9: 500 | BN9: Annual | BO9: Annual | BP9: Annual | BQ9: 500
A10: Large Ag M6 | B10: 50 | C10: 50 | F10: 50 | H10: 50 | I10: 50 | U10: 500 | V10: 1500 | X10: 500 | Y10: 500 | Z10: 500 | AB10: 500 | AC10: 500 | AG10: 500 | AI10: 500 | AK10: 500 | AL10: 1000 | AT10: 500 | AW10: 1000 | BA10: 500 | BB10: 1000 | BF10: 1500 | BG10: 1500 | BH10: 2000 | BJ10: 500 | BK10: 3000 | BN10: Annual | BO10: Annual | BP10: Annual | BQ10: 500
A11: Skid Steer | B11: 50 | D11: 50 | F11: 50 | H11: 50 | I11: 50 | J11: 50 | Q11: 250 | U11: 500 | V11: 1500 | Y11: 500 | Z11: 500 | AB11: 1000 | AE11: 500 | AF11: 500 | AG11: 500 | AI11: 1000 | AS11: 500 | AT11: 500 | AW11: 1000 | BB11: 500 | BF11: 1500 | BG11: 1500 | BH11: 2000 | BJ11: 500 | BN11: Annual | BO11: Annual | BP11: Annual | BQ11: 500
A12: Excavator - under 3.5 ton | B12: 50 | C12: 50 | D12: 50 | H12: 50 | I12: 50 | Q12: 250 | U12: 500 | V12: 1500 | X12: 500 | Z12: 500 | AF12: 1000 | AG12: 1000 | AH12: 1000 | AI12: 1000 | AL12: 1000 | AP12: 500 | AQ12: 500 | AS12: 1000 | AT12: 500 | AW12: 1000 | AZ12: 500 | BB12: 1000 | BH12: 2000 | BJ12: 500 | BN12: Annual | BO12: Annual | BP12: Annual | BQ12: 500
A13: Excavator - over 3.5 ton | B13: 50 | C13: 50 | D13: 50 | H13: 50 | I13: 50 | Q13: 250 | U13: 500 | V13: 1500 | X13: 500 | Z13: 500 | AF13: 1000 | AG13: 1000 | AH13: 1000 | AI13: 1000 | AL13: 1000 | AP13: 500 | AQ13: 500 | AS13: 1000 | AT13: 500 | AW13: 1000 | AZ13: 500 | BB13: 500 | BH13: 2000 | BJ13: 500 | BN13: Annual | BO13: Annual | BP13: Annual | BQ13: 500
A14: Wheel Loader | B14: 50 | C14: 50 | D14: 50 | H14: 50 | I14: 50 | R14: 250 | U14: 500 | V14: 1500 | X14: 500 | Z14: 500 | AG14: 500 | AI14: 1000 | AJ14: 1000 | AP14: 500 | AS14: 1000 | AT14: 500 | AW14: 1000 | BB14: 1000 | BE14: 500 | BH14: 2000 | BJ14: 500 | BN14: Annual | BO14: Annual | BP14: Annual | BQ14: 500
A15: Telehandler | B15: 50 | C15: 50 | D15: 50 | H15: 50 | I15: 50 | R15: 250 | U15: 500 | W15: 500 | X15: 500 | Y15: 500 | Z15: 500 | AG15: 500 | AI15: 1000 | AP15: 500 | AS15: 1000 | AT15: 500 | AW15: 1000 | BB15: 1000 | BE15: 500 | BH15: 2000 | BJ15: 500 | BN15: Annual | BO15: Annual | BP15: Annual | BQ15: 500
A16: Mahindra Emax | B16: 50 | E16: 50 | F16: 50 | H16: 50 | I16: 50 | L16: 50 | U16: 250 | Z16: 250 | AB16: 500 | AE16: 250 | AL16: 500 | AT16: 250 | BB16: 500 | BH16: 1000 | BJ16: 250 | BN16: Annual | BO16: Annual | BP16: Annual | BQ16: 250
A17: Mahindra 1600 Series | B17: 50 | C17: 50 | E17: 50 | F17: 50 | H17: 50 | I17: 50 | K17: 50 | L17: 50 | U17: 100 | W17: 100 | Z17: 100 | AB17: 300 | AE17: 300 | AL17: 400 | AT17: 100 | AW17: 400 | BB17: 300 | BH17: 1000 | BJ17: 100 | BN17: Annual | BO17: Annual | BP17: Annual | BQ17: 100
A18: Mahindra 4500 | B18: 50 | F18: 50 | H18: 50 | I18: 50 | U18: 400 | Z18: 200 | AB18: 1000 | AC18: 1600 | AE18: 400 | AL18: 200 | AT18: 200 | AW18: 1000 | BB18: 800 | BC18: 800 | BF18: 1600 | BH18: 1000 | BJ18: 200 | BN18: Annual | BO18: Annual | BP18: Annual | BQ18: 400
A19: Mahindra 5500 | B19: 50 | F19: 50 | H19: 50 | I19: 50 | U19: 250 | Z19: 500 | AB19: 650 | AC19: 650 | AI19: 2000 | AL19: 650 | AT19: 250 | BB19: 1000 | BC19: 1000 | BF19: 1750 | BH19: 1000 | BJ19: 250 | BN19: Annual | BO19: Annual | BP19: Annual | BQ19: 250
A20: Mahindra 6000 | B20: 50 | F20: 50 | H20: 50 | I20: 50 | U20: 500 | Z20: 250 | AB20: 1250 | AC20: 500 | AI20: 500 | AL20: 500 | AT20: 250 | AW20: 1000 | BB20: 1000 | BC20: 1000 | BF20: 1500 | BH20: 1000 | BJ20: 250 | BN20: Annual | BO20: Annual | BP20: Annual | BQ20: 500
A21: Takeuchi TL 8/10/12 | B21: 50 | C21: 50 | D21: 50 | F21: 50 | H21: 50 | I21: 50 | M21: 50 | P21: 50 | U21: 500 | V21: 1500 | W21: 250 | X21: 1500 | Z21: 500 | AG21: 500 | AH21: 500 | AI21: 1000 | AL21: 250 | AP21: 250 | AQ21: 250 | AT21: 500 | AW21: 1000 | BB21: 250 | BF21: 1500 | BG21: 1500 | BH21: 1000 | BJ21: 500 | BN21: Annual | BO21: Annual | BP21: Annual | BQ21: 500
A22: Takeuchi 228-235-250 | B22: 50 | C22: 50 | H22: 50 | I22: 50 | Q22: 250 | R22: 250 | U22: 250 | X22: 500 | Z22: 500 | AB22: 1000 | AF22: 1000 | AG22: 1000 | AH22: 1000 | AJ22: 1000 | AP22: 250 | AT22: 250 | AW22: 2000 | BB22: 1000 | BC22: 1000 | BF22: 1500 | BG22: 1500 | BH22: 2000 | BJ22: 250 | BN22: Annual | BO22: Annual | BP22: Annual | BQ22: 250
A23: Takeuchi 260 | B23: 50 | D23: 50 | H23: 50 | I23: 50 | Q23: 250 | R23: 250 | U23: 500 | X23: 250 | Z23: 250 | AB23: 1000 | AF23: 1000 | AG23: 1000 | AH23: 1000 | AL23: 1000 | AP23: 250 | AT23: 500 | AW23: 1000 | BB23: 1000 | BC23: 1000 | BF23: 1500 | BH23: 2000 | BJ23: 500 | BN23: Annual | BO23: Annual | BP23: Annual | BQ23: 500
A24: Takeuchi 335 | B24: 50 | H24: 50 | I24: 50 | Q24: 250 | U24: 250 | X24: 500 | Z24: 500 | AB24: 1000 | AF24: 1000 | AG24: 1000 | AH24: 1000 | AP24: 250 | AT24: 250 | AW24: 1000 | AZ24: 500 | BB24: 500 | BC24: 1000 | BF24: 1500 | BH24: 2000 | BJ24: 250 | BN24: Annual | BO24: Annual | BP24: Annual | BQ24: 250
A25: Sany SY up to 35 | B25: 50 | D25: 50 | H25: 50 | I25: 50 | Q25: 100 | R25: 250 | U25: 250 | X25: 500 | Z25: 500 | AF25: 1000 | AG25: 1000 | AH25: 1000 | AI25: 2000 | AK25: 500 | AT25: 250 | BB25: 500 | BH25: 2000 | BJ25: 250 | BN25: Annual | BO25: Annual | BP25: Annual | BQ25: 250
A26: Sany SY up to 60 | B26: 50 | D26: 50 | H26: 50 | I26: 50 | Q26: 100 | R26: 250 | U26: 250 | X26: 500 | Z26: 500 | AF26: 1000 | AG26: 1000 | AH26: 1000 | AI26: 2000 | AK26: 500 | AT26: 250 | BB26: 500 | BH26: 2000 | BJ26: 250 | BN26: Annual | BO26: Annual | BP26: Annual | BQ26: 250
A27: Sany SY up to 155 | B27: 50 | D27: 50 | H27: 50 | I27: 50 | J27: 50 | Q27: 250 | U27: 500 | Z27: 500 | AF27: 500 | AG27: 1000 | AH27: 1000 | AI27: 400 | AK27: 2000 | AT27: 500 | BB27: 500 | BH27: 2000 | BJ27: 500 | BK27: 1000 | BN27: Annual | BO27: Annual | BP27: Annual | BQ27: 500
A28: Sany SY up to 215 | B28: 50 | D28: 50 | H28: 50 | I28: 50 | Q28: 250 | R28: 250 | U28: 500 | Z28: 500 | AF28: 500 | AG28: 1000 | AH28: 500 | AI28: 2000 | AJ28: 500 | AT28: 500 | BB28: 500 | BH28: 2000 | BJ28: 500 | BK28: 1000 | BN28: Annual | BO28: Annual | BP28: Annual | BQ28: 500
A29: Sany SY up to 500 | B29: 50 | D29: 50 | H29: 50 | I29: 50 | Q29: 250 | R29: 250 | U29: 500 | Z29: 500 | AF29: 1000 | AG29: 1000 | AH29: 1000 | AI29: 2000 | AJ29: 2000 | AT29: 500 | BB29: 500 | BC29: 500 | BH29: 2000 | BJ29: 500 | BK29: 1000 | BM29: 500 | BN29: Annual | BO29: Annual | BP29: Annual | BQ29: 500
A30: Sany SW up to 305 | B30: 50 | D30: 50 | E30: 50 | H30: 50 | I30: 50 | K30: 50 | M30: 50 | N30: 50 | U30: 250 | Z30: 500 | AB30: 1000 | AC30: 1000 | AF30: 500 | AG30: 1000 | AH30: 1000 | AI30: 2000 | AJ30: 1000 | AT30: 250 | BB30: 1000 | BC30: 1000 | BH30: 2000 | BJ30: 250 | BK30: 1000 | BL30: 1000 | BN30: Annual | BO30: Annual | BP30: Annual | BQ30: 250
A31: SCL - DIESEL | B31: 50 | F31: 50 | H31: 50 | I31: 50 | U31: 200 | X31: 400 | Z31: 400 | AB31: 400 | AC31: 200 | AE31: 400 | AT31: 200 | AW31: 800 | BB31: 1000 | BC31: 1000 | BH31: 2000 | BI31: 200 | BJ31: 200 | BN31: Annual | BO31: Annual | BP31: Annual | BQ31: 200
A32: SCL - Gas | B32: 8 | H32: 50 | I32: 50 | S32: 100 | U32: 100 | Z32: 100 | AB32: 400 | AC32: 400 | AT32: 100 | BB32: 100 | BD32: 500 | BH32: 100 | BI32: 100 | BJ32: 100 | BN32: Annual | BO32: Annual | BP32: Annual | BQ32: 100
A33: Mini Excavator | B33: 50 | F33: 50 | H33: 50 | I33: 50 | U33: 100 | Z33: 250 | AF33: 1000 | AG33: 250 | AI33: 500 | AT33: 100 | BB33: 250 | BC33: 250 | BH33: 2000 | BJ33: 100 | BN33: Annual | BO33: Annual | BP33: Annual | BQ33: 100
A34: Sub Compact BX | B34: 50 | H34: 50 | I34: 50 | U34: 400 | V34: 1400 | W34: 400 | Z34: 400 | AB34: 400 | AC34: 200 | AE34: 400 | AG34: 400 | AL34: 800 | AT34: 400 | BB34: 1000 | BC34: 1000 | BH34: 2000 | BJ34: 400 | BN34: Annual | BO34: Annual | BP34: Annual | BQ34: 400
B36: =_xlfn.XLOOKUP($A$37,$A$4:$A$34,B4:B34) -> 50 | C36: =_xlfn.XLOOKUP($A$37,$A$4:$A$34,C4:C34) -> 0 | D36: =_xlfn.XLOOKUP($A$37,$A$4:$A$34,D4:D34) -> 0 | E36: =_xlfn.XLOOKUP($A$37,$A$4:$A$34,E4:E34) -> 0 | F36: =_xlfn.XLOOKUP($A$37,$A$4:$A$34,F4:F34) -> 50 | G36: =_xlfn.XLOOKUP($A$37,$A$4:$A$34,G4:G34) -> 0 | H36: =_xlfn.XLOOKUP($A$37,$A$4:$A$34,H4:H34) -> 50 | I36: =_xlfn.XLOOKUP($A$37,$A$4:$A$34,I4:I34) -> 50 | ... BP36: =_xlfn.XLOOKUP($A$37,$A$4:$A$34,BP4:BP34) -> Annual
A37: ='Plan Summary'!C3 -> RTV | B37: =VLOOKUP($A$37,$A$4:$P$34,COLUMN(B1),FALSE) -> 50 | C37: =VLOOKUP($A$37,$A$4:$P$34,COLUMN(C1),FALSE) -> 0 | D37: =VLOOKUP($A$37,$A$4:$P$34,COLUMN(D1),FALSE) -> 0 | E37: =VLOOKUP($A$37,$A$4:$P$34,COLUMN(E1),FALSE) -> 0 | F37: =VLOOKUP($A$37,$A$4:$P$34,COLUMN(F1),FALSE) -> 50 | G37: =VLOOKUP($A$37,$A$4:$P$34,COLUMN(G1),FALSE) -> 0 | H37: =VLOOKUP($A$37,$A$4:$P$34,COLUMN(H1),FALSE) -> 50 | I37: =VLOOKUP($A$37,$A$4:$P$34,COLUMN(I1),FALSE) -> 50 | ... P37: =VLOOKUP($A$37,$A$4:$P$34,COLUMN(P1),FALSE) -> 50 | Q37: =IF(Q36=0,"",IF(Q36<$A40,Q36,"")) | R37: =IF(R36=0,"",IF(R36<$A40,R36,"")) | S37: =IF(S36=0,"",IF(S36<$A40,S36,"")) | T37: =IF(T36=0,"",IF(T36<$A40,T36,"")) | U37: =IF(U36=0,"",IF(U36<=$A40,U36,"")) -> 200 | V37: =IF(V36=0,"",IF(V36<=$A40,V36,"")) | W37: =IF(W36=0,"",IF(W36<=$A40,W36,"")) | X37: =IF(X36=0,"",IF(X36<=$A40,X36,"")) | Y37: =IF(Y36=0,"",IF(Y36<=$A40,Y36,"")) -> 200 | Z37: =IF(Z36=0,"",IF(Z36<=$A40,Z36,"")) | AA37: =IF(AA36=0,"",IF(AA36<=$A40,AA36,"")) | AB37: =IF(AB36=0,"",IF(AB36<=$A40,AB36,"")) | ... BM37: =IF(BM36=0,"",IF(BM36<=$A40,BM36,"")) | BN37: =IF($A42="OK","",1) -> 1 | BO37: =IF($A42="OK","",1) -> 1 | BP37: =IF($A42="OK","",1) -> 1
B38: =IF(B37>0,B2,"") -> Perform Oil and Filter Change | C38: =IF(C37>0,C2,"") | D38: =IF(D37>0,D2,"") | E38: =IF(E37>0,E2,"") | F38: =IF(F37>0,F2,"") -> Change HST Oil Filter | G38: =IF(G37>0,G2,"") | H38: =IF(H37>0,H2,"") -> Grease Machine at required lubrication fittings | I38: =IF(I37>0,I2,"") -> Conduct Multi Point Inpection and make minor adjustments | ... P38: =IF(P37>0,P2,"") -> Change Hydraulic suction return filter | Q38: =IF(Q37<>"",Q2,"") | R38: =IF(R37<>"",R2,"") | S38: =IF(S37<>"",S2,"") | T38: =IF(T37<>"",T2,"") | U38: =IF(U37<>"",U2,"") -> Perform Oil and Filter Change | V38: =IF(V37<>"",V2,"") | W38: =IF(W37<>"",W2,"") | X38: =IF(X37<>"",X2,"") | ... BP38: =IF(BP37<>"",BP2,"") -> Conduct Annual Multi Point Inpection and Make Minor Adjustments
B39: =IF(B38>"", _xlfn.XLOOKUP($A$37,'Total Cost Per Service)'!$A4:$A34,'Total Cost Per Service)'!B4:B34),"") -> 89.63 | C39: =IF(C38>"", _xlfn.XLOOKUP($A$37,'Total Cost Per Service)'!$A4:$A34,'Total Cost Per Service)'!C4:C34),"") | D39: =IF(D38>"", _xlfn.XLOOKUP($A$37,'Total Cost Per Service)'!$A4:$A34,'Total Cost Per Service)'!D4:D34),"") | E39: =IF(E38>"", _xlfn.XLOOKUP($A$37,'Total Cost Per Service)'!$A4:$A34,'Total Cost Per Service)'!E4:E34),"") | F39: =IF(F38>"", _xlfn.XLOOKUP($A$37,'Total Cost Per Service)'!$A4:$A34,'Total Cost Per Service)'!F4:F34),"") -> 148.69 | G39: =IF(G38>"", _xlfn.XLOOKUP($A$37,'Total Cost Per Service)'!$A4:$A34,'Total Cost Per Service)'!G4:G34),"") | H39: =IF(H38>"", _xlfn.XLOOKUP($A$37,'Total Cost Per Service)'!$A4:$A34,'Total Cost Per Service)'!H4:H34),"") -> 23.07 | I39: =IF(I38>"", _xlfn.XLOOKUP($A$37,'Total Cost Per Service)'!$A4:$A34,'Total Cost Per Service)'!I4:I34),"") -> 30 | ... BP39: =IF(BP38>"", _xlfn.XLOOKUP($A$37,'Total Cost Per Service)'!$A4:$A34,'Total Cost Per Service)'!BP4:BP34),"") -> 126
A40: ='Plan Summary'!C5 -> 300 | Q40: =IF(Q37<=$A40,Q37,"") | R40: =IF(R37<=$A40,R37,"") | S40: =IF(S37<=$A40,S37,"") | T40: =IF(T37<=$A40,T37,"") | U40: =IF(U37<=$A40,U37,"") -> 200 | V40: =IF(V37<=$A40,V37,"") | W40: =IF(W37<=$A40,W37,"") | X40: =IF(X37<=$A40,X37,"") | ... BP40: =IF(BP37<=$A40,BP37,"") -> 1
A41: ='Plan Summary'!C9/12 -> 5 | B41: =CONCATENATE(B37," hours ",B38) -> 50 hours Perform Oil and Filter Change | C41: =+C38 | D41: =+D38 | E41: =+E38 | F41: =+F38 -> Change HST Oil Filter | G41: =+G38 | H41: =+H38 -> Grease Machine at required lubrication fittings | I41: =+I38 -> Conduct Multi Point Inpection and make minor adjustments | J41: =+J38 | ... P41: =+P38 -> Change Hydraulic suction return filter | Q41: =IF(Q40<>"",CONCATENATE("AT INITIAL ", Q40," hours - ",Q38),"") | R41: =IF(R40<>"",CONCATENATE("AT INITIAL ", R40," hours - ",R38),"") | S41: =IF(S40<>"",CONCATENATE("AT INITIAL ", S40," hours - ",S38),"") | T41: =IF(T40<>"",CONCATENATE("AT INITIAL ", T40," hours - ",T38),"") | U41: =IF(U40<>"",CONCATENATE("Every ", U40," hours - ",U38),"") -> Every 200 hours - Perform Oil and Filter Change | V41: =IF(V40<>"",CONCATENATE("Every ", V40," hours - ",V38),"") | W41: =IF(W40<>"",CONCATENATE("Every ", W40," hours - ",W38),"") | X41: =IF(X40<>"",CONCATENATE("Every ", X40," hours - ",X38),"") | Y41: =IF(Y40<>"",CONCATENATE("Every ", Y40," hours - ",Y38),"") -> Every 200 hours - Drain Water from Fuel Tank | Z41: =IF(Z40<>"",CONCATENATE("Every ", Z40," hours - ",Z38),"") | AA41: =IF(AA40<>"",CONCATENATE("Every ", AA40," hours - ",AA38),"") | AB41: =IF(AB40<>"",CONCATENATE("Every ", AB40," hours - ",AB38),"") | ... BM41: =IF(BM40<>"",CONCATENATE("Every ", BM40," hours - ",BM38),"") | BN41: =IF(BN40<>"",BN38,"") -> Perform Annual Oil and Filter Change | BO41: =IF(BO40<>"",BO38,"") -> Annually Grease Machine at Assorted Lubrication Points | BP41: =IF(BP40<>"",BP38,"") -> Conduct Annual Multi Point Inpection and Make Minor Adjustments | BQ41: =IF(BQ40<>0,CONCATENATE("First Service ", BQ40," hours - ",BQ38),"")
...

Sheet Hours Per Job
B1: FIRST SERVICES | Q1: ONE TIME SERVICE | U1: Included Maintenance Interval
A2: HOURS PER JOB | B2: =+'Scheduled Intervals'!B2 -> Perform Oil and Filter Change | C2: =+'Scheduled Intervals'!C2 -> Clean Water seperator | D2: =+'Scheduled Intervals'!D2 -> Drain Water from Fuel Tank | E2: =+'Scheduled Intervals'!E2 -> Perform Transmission Filter and Fluid Service | F2: =+'Scheduled Intervals'!F2 -> Change HST Oil Filter | G2: =+'Scheduled Intervals'!G2 -> Change Hydraulic Fluid | H2: =+'Scheduled Intervals'!H2 -> Grease Machine at required lubrication fittings | I2: =+'Scheduled Intervals'!I2 -> Conduct Multi Point Inpection and make minor adjustments | ... BP2: =+'Scheduled Intervals'!BP2 -> Conduct Annual Multi Point Inpection and Make Minor Adjustments
A3: Job Description | B3: =+'Scheduled Intervals'!B3 -> Parts and Labor | C3: =+'Scheduled Intervals'!C3 -> Labor Only | D3: =+'Scheduled Intervals'!D3 -> Labor Only | E3: =+'Scheduled Intervals'!E3 -> Parts and Labor | F3: =+'Scheduled Intervals'!F3 -> Parts and Labor | G3: =+'Scheduled Intervals'!G3 -> Parts and Labor | H3: =+'Scheduled Intervals'!H3 -> Parts and Labor | I3: =+'Scheduled Intervals'!I3 -> Labor Only | ... Q3: =+'Scheduled Intervals'!Q3 -> Parts and Labor | R3: Parts and Labor | S3: =+'Scheduled Intervals'!S3 -> Parts and Labor | T3: =+'Scheduled Intervals'!T3 -> Parts and Labor | U3: =+'Scheduled Intervals'!U3 -> Parts and Labor | V3: =+'Scheduled Intervals'!V3 -> Parts and Labor | W3: =+'Scheduled Intervals'!W3 -> Labor Only | X3: =+'Scheduled Intervals'!X3 -> Parts and Labor | Y3: =+'Scheduled Intervals'!Y3 -> Labor Only | Z3: =+'Scheduled Intervals'!Z3 -> Parts and Labor | ... BP3: =+'Scheduled Intervals'!BP3 -> Labor Only
A4: =+'Scheduled Intervals'!A4 -> RTV | B4: 0.4 | F4: 0.8 | H4: 0.1 | I4: 0.25 | P4: 0.1 | U4: 0.4 | Y4: 0.1 | Z4: 0.2 | AB4: 0.6 | AC4: 0.2 | AE4: 0.2 | AI4: 0.9 | AL4: 0.5 | AT4: 0.1 | AW4: 1.5 | BB4: 0.1 | BC4: 0.1 | BD4: 0.4 | BH4: 0.5 | BJ4: 0.25 | BN4: 0.4 | BO4: 0.1 | BP4: 1.05
A5: =+'Scheduled Intervals'!A5 -> Zero Turn Gas | B5: 0.3 | H5: 0.2 | I5: 0.25 | S5: 0.9 | U5: 0.3 | Z5: 0.2 | AB5: 0.7 | AC5: 0.2 | AT5: 0.2 | BB5: 0.1 | BD5: 0.2 | BH5: 0.3 | BI5: 0.1 | BJ5: 0.25 | BN5: 0.3 | BO5: 0.2 | BP5: 1.05
A6: =+'Scheduled Intervals'!A6 -> Zero Turn Diesel | B6: 0.3 | F6: 0.4 | H6: 0.2 | I6: 0.25 | U6: 0.3 | X6: 0.2 | Z6: 0.5 | AB6: 0.7 | AC6: 0.2 | AE6: 0.1 | AT6: 0.2 | AW6: 0.3 | BB6: 0.1 | BC6: 0.1 | BH6: 0.3 | BI6: 0.1 | BJ6: 0.25 | BN6: 0.3 | BO6: 0.2 | BP6: 1.05
A7: =+'Scheduled Intervals'!A7 -> Compact L series | B7: 0.4 | F7: 0.5 | H7: 0.2 | I7: 0.25 | M7: 0.6 | U7: 0.4 | Z7: 0.1 | AB7: 0.7 | AC7: 0.2 | AE7: 0.2 | AL7: 1 | AP7: 0.3 | AQ7: 0.2 | AT7: 0.2 | AW7: 6 | BB7: 0.1 | BH7: 0.4 | BJ7: 0.25 | BN7: 0.4 | BO7: 0.2 | BP7: 1.05
A8: =+'Scheduled Intervals'!A8 -> Utility under 75 MX&M | B8: 0.4 | F8: 0.7 | H8: 0.2 | I8: 0.25 | U8: 0.4 | V8: 0.2 | W8: 0.1 | Y8: 0.1 | Z8: 0.1 | AB8: 1 | AE8: 0.9 | AL8: 1.6 | AP8: 0.3 | AQ8: 0.2 | AS8: 0.3 | AT8: 0.2 | BB8: 0.2 | BC8: 0.2 | BF8: 0.75 | BG8: 2 | BH8: 0.4 | BJ8: 0.25 | BN8: 0.4 | BO8: 0.2 | BP8: 1.05
A9: =+'Scheduled Intervals'!A9 -> Utility over 75 M4 class | B9: 0.4 | H9: 0.2 | I9: 0.25 | U9: 0.4 | V9: 0.2 | W9: 0.4 | Y9: 0.2 | Z9: 0.2 | AB9: 1.1 | AE9: 1 | AJ9: 1.7 | AS9: 0.3 | AT9: 0.2 | AW9: 6.9 | BB9: 0.1 | BF9: 0.75 | BG9: 2 | BH9: 0.5 | BJ9: 0.25 | BN9: 0.4 | BO9: 0.2 | BP9: 1.05
A10: =+'Scheduled Intervals'!A10 -> Large Ag M6 | B10: 0.6 | C10: 0.4 | F10: 0.5 | H10: 0.5 | I10: 0.25 | U10: 0.6 | V10: 0.2 | X10: 0.4 | Y10: 0.3 | Z10: 0.3 | AB10: 4 | AC10: 2.1 | AG10: 0.5 | AI10: 2.1 | AK10: 2.5 | AL10: 2.5 | AT10: 0.5 | AW10: 5 | BA10: 0.1 | BB10: 0.2 | BF10: 0.75 | BG10: 2 | BH10: 1.6 | BJ10: 0.25 | BK10: 2 | BN10: 0.6 | BO10: 0.5 | BP10: 1.05
A11: =+'Scheduled Intervals'!A11 -> Skid Steer | B11: 0.8 | D11: 0.3 | F11: 0.5 | H11: 0.5 | I11: 0.25 | J11: 0.5 | Q11: 1 | U11: 0.8 | V11: 0.2 | Y11: 0.3 | Z11: 0.4 | AB11: 1 | AE11: 0.5 | AF11: 0.1 | AG11: 0.5 | AI11: 1.8 | AS11: 0.2 | AT11: 0.5 | AW11: 6.9 | BB11: 0.2 | BF11: 0.75 | BG11: 2 | BH11: 0.6 | BJ11: 0.25 | BN11: 0.8 | BO11: 0.5 | BP11: 1.05
A12: =+'Scheduled Intervals'!A12 -> Excavator - under 3.5 ton | B12: 0.7 | C12: 0.3 | D12: 0.1 | H12: 0.5 | I12: 0.25 | Q12: 1 | U12: 0.7 | V12: 0.2 | X12: 0.2 | Z12: 0.2 | AF12: 0.1 | AG12: 0.5 | AH12: 0.6 | AI12: 1 | AL12: 1.5 | AP12: 0.25 | AQ12: 0.2 | AS12: 1 | AT12: 0.5 | AW12: 1.7 | AZ12: 1 | BB12: 0.1 | BH12: 0.4 | BJ12: 0.25 | BN12: 0.7 | BO12: 0.5 | BP12: 1.05
A13: =+'Scheduled Intervals'!A13 -> Excavator - over 3.5 ton | B13: 1 | C13: 0.3 | D13: 0.1 | H13: 0.5 | I13: 0.25 | Q13: 1 | U13: 1 | V13: 0.2 | X13: 0.2 | Z13: 0.3 | AF13: 0.1 | AG13: 0.6 | AH13: 0.6 | AI13: 2 | AL13: 1.5 | AP13: 0.7 | AQ13: 0.2 | AS13: 0.1 | AT13: 0.5 | AW13: 2.2 | AZ13: 1 | BB13: 0.1 | BH13: 0.7 | BJ13: 0.25 | BN13: 1 | BO13: 0.5 | BP13: 1.05
A14: =+'Scheduled Intervals'!A14 -> Wheel Loader | B14: 1 | C14: 0.3 | D14: 0.1 | H14: 0.4 | I14: 0.25 | R14: 2 | U14: 1 | V14: 0.2 | X14: 0.3 | Z14: 0.1 | AG14: 0.5 | AI14: 2 | AJ14: 1 | AP14: 0.3 | AS14: 0.3 | AT14: 0.4 | AW14: 4.3 | BB14: 0.1 | BE14: 0.2 | BH14: 0.8 | BJ14: 0.25 | BN14: 1 | BO14: 0.4 | BP14: 1.05
A15: =+'Scheduled Intervals'!A15 -> Telehandler | B15: 1 | C15: 0.3 | D15: 0.1 | H15: 0.4 | I15: 0.25 | R15: 1 | U15: 1 | W15: 0.3 | X15: 0.3 | Y15: 0.1 | Z15: 0.1 | AG15: 0.5 | AI15: 2 | AP15: 0.3 | AS15: 0.3 | AT15: 0.4 | AW15: 4.3 | BB15: 0.1 | BE15: 0.2 | BH15: 0.8 | BJ15: 0.25 | BN15: 1 | BO15: 0.4 | BP15: 1.05
A16: =+'Scheduled Intervals'!A16 -> Mahindra Emax | B16: 0.3 | E16: 1 | F16: 0.5 | H16: 0.2 | I16: 0.25 | L16: 1 | U16: 0.3 | Z16: 0.1 | AB16: 1 | AE16: 0.5 | AL16: 1 | AT16: 0.2 | BB16: 0.1 | BH16: 1 | BJ16: 0.25 | BN16: 0.3 | BO16: 0.2 | BP16: 1.05
A17: =+'Scheduled Intervals'!A17 -> Mahindra 1600 Series | B17: 0.4 | C17: 0.1 | E17: 1 | F17: 0.5 | H17: 0.2 | I17: 0.25 | K17: 0.2 | L17: 1 | U17: 0.4 | W17: 0.1 | Z17: 0.2 | AB17: 1 | AE17: 0.5 | AL17: 1 | AT17: 0.2 | AW17: 2 | BB17: 0.1 | BH17: 1 | BJ17: 0.25 | BN17: 0.4 | BO17: 0.2 | BP17: 1.05
A18: =+'Scheduled Intervals'!A18 -> Mahindra 4500 | B18: 0.4 | F18: 0.5 | H18: 0.2 | I18: 0.25 | U18: 0.4 | Z18: 0.3 | AB18: 1 | AC18: 0.3 | AE18: 0.5 | AL18: 1 | AT18: 0.2 | AW18: 3 | BB18: 0.1 | BC18: 0.2 | BF18: 0.75 | BH18: 1 | BJ18: 0.25 | BN18: 0.4 | BO18: 0.2 | BP18: 1.05
A19: =+'Scheduled Intervals'!A19 -> Mahindra 5500 | B19: 0.4 | F19: 0.5 | H19: 0.2 | I19: 0.25 | U19: 0.4 | Z19: 0.3 | AB19: 1 | AC19: 0.3 | AI19: 1 | AL19: 1 | AT19: 0.2 | BB19: 0.1 | BC19: 0.2 | BF19: 0.75 | BH19: 1 | BJ19: 0.25 | BN19: 0.4 | BO19: 0.2 | BP19: 1.05
A20: =+'Scheduled Intervals'!A20 -> Mahindra 6000 | B20: 0.4 | F20: 0.5 | H20: 0.2 | I20: 0.25 | U20: 0.4 | Z20: 0.3 | AB20: 1 | AC20: 0.3 | AI20: 1 | AL20: 1 | AT20: 0.2 | AW20: 5 | BB20: 0.1 | BC20: 0.2 | BF20: 0.75 | BH20: 1 | BJ20: 0.25 | BN20: 0.4 | BO20: 0.2 | BP20: 1.05
A21: =+'Scheduled Intervals'!A21 -> Takeuchi TL 8/10/12 | B21: 0.7 | C21: 0.1 | D21: 0.1 | F21: 0.7 | H21: 0.5 | I21: 0.25 | M21: 0.6 | P21: 0.5 | U21: 0.7 | V21: 0.2 | W21: 0.1 | X21: 0.2 | Z21: 0.3 | AG21: 0.5 | AH21: 0.5 | AI21: 1 | AL21: 1 | AP21: 0.7 | AQ21: 0.2 | AT21: 0.5 | AW21: 5 | BB21: 0.1 | BF21: 0.75 | BG21: 0.75 | BH21: 1 | BJ21: 0.25 | BN21: 0.7 | BO21: 0.5 | BP21: 1.05
A22: =+'Scheduled Intervals'!A22 -> Takeuchi 228-235-250 | B22: 0.7 | C22: 0.1 | H22: 0.5 | I22: 0.25 | Q22: 0.7 | R22: 1 | U22: 0.7 | X22: 0.2 | Z22: 0.3 | AB22: 1 | AF22: 0.1 | AG22: 0.5 | AH22: 0.5 | AJ22: 1 | AP22: 0.7 | AT22: 0.5 | AW22: 5 | BB22: 0.1 | BC22: 0.2 | BF22: 0.75 | BG22: 0.75 | BH22: 1 | BJ22: 0.25 | BN22: 0.7 | BO22: 0.5 | BP22: 1.05
A23: =+'Scheduled Intervals'!A23 -> Takeuchi 260 | B23: 0.7 | D23: 0.1 | H23: 0.5 | I23: 0.25 | Q23: 0.6 | R23: 1 | U23: 0.7 | X23: 0.2 | Z23: 0.3 | AB23: 1 | AF23: 0.1 | AG23: 0.5 | AH23: 0.5 | AL23: 1 | AP23: 0.7 | AT23: 0.5 | AW23: 5 | BB23: 0.1 | BC23: 0.2 | BF23: 0.75 | BH23: 1 | BJ23: 0.25 | BN23: 0.7 | BO23: 0.5 | BP23: 1.05
A24: =+'Scheduled Intervals'!A24 -> Takeuchi 335 | B24: 0.7 | H24: 0.5 | I24: 0.25 | Q24: 0.7 | U24: 0.7 | X24: 0.2 | Z24: 0.3 | AB24: 1 | AF24: 0.1 | AG24: 0.5 | AH24: 0.5 | AP24: 0.7 | AT24: 0.5 | AW24: 5 | AZ24: 1 | BB24: 0.1 | BC24: 0.2 | BF24: 0.75 | BH24: 1 | BJ24: 0.25 | BN24: 0.7 | BO24: 0.5 | BP24: 1.05
A25: =+'Scheduled Intervals'!A25 -> Sany SY up to 35 | B25: 0.7 | D25: 0.1 | H25: 0.5 | I25: 0.25 | Q25: 0.5 | R25: 1 | U25: 0.7 | X25: 0.2 | Z25: 0.3 | AF25: 0.1 | AG25: 0.5 | AH25: 0.5 | AI25: 1 | AK25: 1 | AT25: 0.5 | BB25: 0.1 | BH25: 1 | BJ25: 0.25 | BN25: 0.7 | BO25: 0.5 | BP25: 1.05
A26: =+'Scheduled Intervals'!A26 -> Sany SY up to 60 | B26: 0.7 | D26: 0.1 | H26: 0.5 | I26: 0.25 | Q26: 0.5 | R26: 1 | U26: 0.7 | X26: 0.2 | Z26: 0.3 | AF26: 0.1 | AG26: 0.5 | AH26: 0.5 | AI26: 1 | AK26: 1 | AT26: 0.5 | BB26: 0.1 | BH26: 1 | BJ26: 0.25 | BN26: 0.7 | BO26: 0.5 | BP26: 1.05
A27: =+'Scheduled Intervals'!A27 -> Sany SY up to 155 | B27: 0.7 | D27: 0.1 | H27: 0.5 | I27: 0.25 | J27: 0.5 | Q27: 0.5 | U27: 0.7 | Z27: 0.3 | AF27: 0.1 | AG27: 0.5 | AH27: 0.5 | AI27: 1 | AK27: 1 | AT27: 0.5 | BB27: 0.1 | BH27: 1 | BJ27: 0.25 | BK27: 2 | BN27: 0.7 | BO27: 0.5 | BP27: 1.05
A28: =+'Scheduled Intervals'!A28 -> Sany SY up to 215 | B28: 0.7 | D28: 0.1 | H28: 0.7 | I28: 0.25 | Q28: 0.5 | R28: 1 | U28: 0.7 | Z28: 0.3 | AF28: 0.1 | AG28: 0.5 | AH28: 0.5 | AI28: 1 | AJ28: 1 | AT28: 0.7 | BB28: 0.1 | BH28: 1 | BJ28: 0.25 | BK28: 2 | BN28: 0.7 | BO28: 0.7 | BP28: 1.05
A29: =+'Scheduled Intervals'!A29 -> Sany SY up to 500 | B29: 1 | D29: 0.1 | H29: 0.7 | I29: 0.25 | Q29: 0.5 | R29: 1 | U29: 1 | Z29: 0.3 | AF29: 0.1 | AG29: 0.5 | AH29: 0.5 | AI29: 1.5 | AJ29: 1 | AT29: 0.7 | BB29: 0.1 | BC29: 0.2 | BH29: 1.5 | BJ29: 0.25 | BK29: 2 | BM29: 1 | BN29: 1 | BO29: 0.7 | BP29: 1.05
A30: =+'Scheduled Intervals'!A30 -> Sany SW up to 305 | B30: 1 | D30: 0.3 | E30: 1.5 | H30: 0.7 | I30: 0.25 | K30: 0.3 | M30: 0.5 | N30: 1 | U30: 1 | Z30: 0.3 | AB30: 1 | AC30: 0.3 | AF30: 0.1 | AG30: 0.5 | AH30: 0.5 | AI30: 1.5 | AJ30: 1 | AT30: 0.7 | BB30: 0.1 | BC30: 0.2 | BH30: 1.5 | BJ30: 0.25 | BK30: 2 | BL30: 0.5 | BN30: 1 | BO30: 0.7 | BP30: 1.05
A31: =+'Scheduled Intervals'!A31 -> SCL - DIESEL | B31: 0.3 | F31: 0.4 | H31: 0.2 | I31: 0.25 | U31: 0.3 | X31: 0.2 | Z31: 0.5 | AB31: 0.7 | AC31: 0.2 | AE31: 0.1 | AT31: 0.2 | AW31: 0.3 | BB31: 0.1 | BC31: 0.1 | BH31: 0.3 | BI31: 0.1 | BJ31: 0.25 | BN31: 0.3 | BO31: 0.2 | BP31: 1.05
A32: =+'Scheduled Intervals'!A32 -> SCL - Gas | B32: 0.3 | H32: 0.2 | I32: 0.25 | S32: 0.9 | U32: 0.3 | Z32: 0.2 | AB32: 0.7 | AC32: 0.2 | AT32: 0.2 | BB32: 0.1 | BD32: 0.2 | BH32: 0.3 | BI32: 0.1 | BJ32: 0.25 | BN32: 0.3 | BO32: 0.2 | BP32: 1.05
A33: =+'Scheduled Intervals'!A33 -> Mini Excavator | B33: 0.4 | F33: 0.3 | H33: 0.2 | I33: 0.25 | U33: 0.4 | Z33: 0.2 | AF33: 0.1 | AG33: 0.5 | AI33: 1 | AT33: 0.2 | BB33: 0.1 | BC33: 0.2 | BH33: 1 | BJ33: 0.25 | BN33: 0.4 | BO33: 0.2 | BP33: 1.05
A34: =+'Scheduled Intervals'!A34 -> Sub Compact BX | B34: 0.4 | H34: 0.2 | I34: 0.25 | U34: 0.4 | V34: 0.2 | W34: 0.1 | Z34: 0.2 | AB34: 1 | AC34: 0.3 | AE34: 0.3 | AG34: 0.5 | AL34: 1 | AT34: 0.2 | BB34: 0.1 | BC34: 0.2 | BH34: 1 | BJ34: 0.25 | BN34: 0.4 | BO34: 0.2 | BP34: 1.05
A37: ='Scheduled Intervals'!A4 -> RTV | B37: ='Scheduled Intervals'!B4 -> 50 | C37: ='Scheduled Intervals'!C4 -> 0 | D37: ='Scheduled Intervals'!D4 -> 0 | E37: ='Scheduled Intervals'!E4 -> 0 | F37: ='Scheduled Intervals'!F4 -> 50 | G37: ='Scheduled Intervals'!G4 -> 0 | H37: ='Scheduled Intervals'!H4 -> 50 | ... BP37: ='Scheduled Intervals'!BP4 -> Annual
B38: ='Scheduled Intervals'!B5 -> 8 | C38: ='Scheduled Intervals'!C5 -> 0 | D38: ='Scheduled Intervals'!D5 -> 0 | E38: ='Scheduled Intervals'!E5 -> 0 | F38: ='Scheduled Intervals'!F5 -> 0 | G38: ='Scheduled Intervals'!G5 -> 0 | H38: ='Scheduled Intervals'!H5 -> 50 | I38: ='Scheduled Intervals'!I5 -> 50 | ... BP38: ='Scheduled Intervals'!BP5 -> Annual
B39: ='Scheduled Intervals'!B6 -> 50 | C39: ='Scheduled Intervals'!C6 -> 0 | D39: ='Scheduled Intervals'!D6 -> 0 | E39: ='Scheduled Intervals'!E6 -> 0 | F39: ='Scheduled Intervals'!F6 -> 50 | G39: ='Scheduled Intervals'!G6 -> 0 | H39: ='Scheduled Intervals'!H6 -> 50 | I39: ='Scheduled Intervals'!I6 -> 50 | ... BP39: ='Scheduled Intervals'!BP6 -> Annual
B40: ='Scheduled Intervals'!B7 -> 50 | C40: ='Scheduled Intervals'!C7 -> 0 | D40: ='Scheduled Intervals'!D7 -> 0 | E40: ='Scheduled Intervals'!E7 -> 0 | F40: ='Scheduled Intervals'!F7 -> 50 | G40: ='Scheduled Intervals'!G7 -> 0 | H40: ='Scheduled Intervals'!H7 -> 50 | I40: ='Scheduled Intervals'!I7 -> 50 | ... BP40: ='Scheduled Intervals'!BP7 -> Annual
B41: ='Scheduled Intervals'!B8 -> 50 | C41: ='Scheduled Intervals'!C8 -> 0 | D41: ='Scheduled Intervals'!D8 -> 0 | E41: ='Scheduled Intervals'!E8 -> 0 | F41: ='Scheduled Intervals'!F8 -> 50 | G41: ='Scheduled Intervals'!G8 -> 0 | H41: ='Scheduled Intervals'!H8 -> 50 | I41: ='Scheduled Intervals'!I8 -> 50 | ... BP41: ='Scheduled Intervals'!BP8 -> Annual
B42: ='Scheduled Intervals'!B9 -> 50 | C42: ='Scheduled Intervals'!C9 -> 0 | D42: ='Scheduled Intervals'!D9 -> 0 | E42: ='Scheduled Intervals'!E9 -> 0 | F42: ='Scheduled Intervals'!F9 -> 0 | G42: ='Scheduled Intervals'!G9 -> 0 | H42: ='Scheduled Intervals'!H9 -> 50 | I42: ='Scheduled Intervals'!I9 -> 50 | ... BP42: ='Scheduled Intervals'!BP9 -> Annual
...

Sheet Parts Cost Per Job
B1: FIRST SERVICES | Q1: ONE TIME SERVICE | U1: Included Maintenance Interval
A2: PRICE FOR PARTS FOR JOB | B2: =+'Scheduled Intervals'!B2 -> Perform Oil and Filter Change | C2: =+'Scheduled Intervals'!C2 -> Clean Water seperator | D2: =+'Scheduled Intervals'!D2 -> Drain Water from Fuel Tank | E2: =+'Scheduled Intervals'!E2 -> Perform Transmission Filter and Fluid Service | F2: =+'Scheduled Intervals'!F2 -> Change HST Oil Filter | G2: =+'Scheduled Intervals'!G2 -> Change Hydraulic Fluid | H2: =+'Scheduled Intervals'!H2 -> Grease Machine at required lubrication fittings | I2: =+'Scheduled Intervals'!I2 -> Conduct Multi Point Inpection and make minor adjustments | ... BP2: =+'Scheduled Intervals'!BP2 -> Conduct Annual Multi Point Inpection and Make Minor Adjustments
A3: Job Description | B3: =+'Scheduled Intervals'!B3 -> Parts and Labor | C3: =+'Scheduled Intervals'!C3 -> Labor Only | D3: =+'Scheduled Intervals'!D3 -> Labor Only | E3: =+'Scheduled Intervals'!E3 -> Parts and Labor | F3: =+'Scheduled Intervals'!F3 -> Parts and Labor | G3: =+'Scheduled Intervals'!G3 -> Parts and Labor | H3: =+'Scheduled Intervals'!H3 -> Parts and Labor | I3: =+'Scheduled Intervals'!I3 -> Labor Only | ... BP3: =+'Scheduled Intervals'!BP3 -> Labor Only | BQ3: =+'Scheduled Intervals'!BP3 -> Labor Only
A4: =+'Scheduled Intervals'!A4 -> RTV | B4: 28.59 | F4: 36.19 | H4: 7.6 | P4: 32.91 | U4: 28.59 | Z4: 14.82 | AB4: 35.6 | AC4: 18.59 | AE4: 36.19 | AI4: 84.55 | AL4: 6.21 | AT4: 7.6 | AW4: 85.04 | BB4: 36.19 | BC4: 39.82 | BD4: 21.2 | BH4: 21.54 | BN4: 28.59 | BO4: 7.6
A5: =+'Scheduled Intervals'!A5 -> Zero Turn Gas | B5: 19.25 | H5: 7.6 | S5: 24.48 | U5: 19.25 | Z5: 10.4 | AB5: 13.35 | AC5: 11.13 | AT5: 7.6 | BB5: 27.09 | BD5: 1.17 | BH5: 21.54 | BN5: 19.25 | BO5: 7.6
A6: =+'Scheduled Intervals'!A6 -> Zero Turn Diesel | B6: 30.85 | F6: 18.59 | H6: 7.6 | U6: 30.85 | X6: 36.35 | Z6: 18.18 | AB6: 57.85 | AC6: 36.19 | AE6: 18.59 | AT6: 7.6 | AW6: 85.4 | BB6: 21.18 | BC6: 16.25 | BH6: 21.54 | BN6: 30.85 | BO6: 7.6
A7: =+'Scheduled Intervals'!A7 -> Compact L series | B7: 31.54 | F7: 18.59 | H7: 7.6 | M7: 18.59 | U7: 31.54 | Z7: 14.82 | AB7: 133.5 | AC7: 18.59 | AE7: 18.59 | AL7: 31.05 | AT7: 7.6 | AW7: 99.2 | BB7: 28.05 | BH7: 21.54 | BN7: 31.54 | BO7: 7.6
A8: =+'Scheduled Intervals'!A8 -> Utility under 75 MX&M | B8: 39.84 | F8: 53.19 | H8: 7.6 | U8: 39.84 | V8: 65.15 | Z8: 22.33 | AB8: 204.7 | AE8: 53.19 | AL8: 55.89 | AS8: 26.17 | AT8: 7.6 | BB8: 21.18 | BC8: 16.25 | BH8: 10.77 | BN8: 39.84 | BO8: 7.6
A9: =+'Scheduled Intervals'!A9 -> Utility over 75 M4 class | B9: 65.7 | H9: 7.6 | U9: 65.7 | V9: 15.44 | Z9: 21.35 | AB9: 222.5 | AE9: 51.18 | AJ9: 62.1 | AS9: 26.17 | AT9: 7.6 | AW9: 115.71 | BB9: 18.72 | BH9: 32.31 | BN9: 65.7 | BO9: 7.6
A10: =+'Scheduled Intervals'!A10 -> Large Ag M6 | B10: 114.33 | F10: 69.02 | H10: 7.6 | U10: 114.33 | V10: 70.77 | X10: 25.82 | Z10: 25.82 | AB10: 400.5 | AC10: 131.92 | AG10: 103.03 | AI10: 66.72 | AK10: 68.31 | AL10: 74.52 | AT10: 7.6 | AW10: 121.25 | BA10: 169.18 | BB10: 102.51 | BH10: 75.39 | BK10: 271.45 | BN10: 114.33 | BO10: 7.6
A11: =+'Scheduled Intervals'!A11 -> Skid Steer | B11: 59.44 | F11: 53.19 | H11: 7.6 | Q11: 81.25 | U11: 59.45 | V11: 65.15 | Z11: 15.23 | AB11: 133.5 | AE11: 53.19 | AF11: 47.4 | AG11: 81.25 | AI11: 53.4 | AS11: 106.73 | AT11: 7.6 | AW11: 121.25 | BB11: 31.34 | BH11: 32.31 | BN11: 59.45 | BO11: 7.6
A12: =+'Scheduled Intervals'!A12 -> Excavator - under 3.5 ton | B12: 56.44 | H12: 7.6 | Q12: 80.17 | U12: 56.44 | V12: 85.67 | X12: 60.85 | Z12: 25.45 | AF12: 16.15 | AG12: 55.82 | AH12: 24.35 | AI12: 51.83 | AL12: 12.42 | AS12: 29.04 | AT12: 7.6 | AW12: 41.27 | AZ12: 63.12 | BB12: 54.4 | BH12: 32.31 | BN12: 56.44 | BO12: 7.6
A13: =+'Scheduled Intervals'!A13 -> Excavator - over 3.5 ton | B13: 56.44 | H13: 7.6 | Q13: 80.17 | U13: 56.44 | V13: 85.67 | X13: 60.85 | Z13: 25.45 | AF13: 16.15 | AG13: 55.82 | AH13: 24.35 | AI13: 170.93 | AL13: 12.42 | AS13: 47.14 | AT13: 7.6 | AW13: 99.2 | AZ13: 63.12 | BB13: 54.4 | BH13: 32.31 | BN13: 56.44 | BO13: 7.6
A14: =+'Scheduled Intervals'!A14 -> Wheel Loader | B14: 55.3 | H14: 7.6 | R14: 49.68 | U14: 55.3 | V14: 61.39 | X14: 32.51 | Z14: 79.46 | AG14: 64.8 | AI14: 326.79 | AJ14: 49.68 | AS14: 67.64 | AT14: 7.6 | AW14: 117.73 | BB14: 116.14 | BH14: 32.31 | BN14: 55.3 | BO14: 7.6
A15: =+'Scheduled Intervals'!A15 -> Telehandler | B15: 109.5 | H15: 7.6 | R15: 52.55 | U15: 109.5 | X15: 32.86 | Z15: 47.75 | AG15: 81.33 | AI15: 341.74 | AS15: 58.48 | AT15: 7.6 | AW15: 124.98 | BB15: 30.75 | BH15: 32.31 | BN15: 109.5 | BO15: 7.6
A16: =+'Scheduled Intervals'!A16 -> Mahindra Emax | B16: 33.97 | E16: 102.35 | F16: 21.28 | H16: 7.6 | L16: 24.84 | U16: 33.97 | Z16: 41.41 | AB16: 102.35 | AE16: 21.28 | AL16: 24.84 | AT16: 7.6 | BB16: 29.8 | BH16: 21.54 | BN16: 33.97 | BO16: 7.6
A17: =+'Scheduled Intervals'!A17 -> Mahindra 1600 Series | B17: 26.63 | E17: 192.56 | F17: 30.21 | H17: 7.6 | K17: 59.02 | L17: 31.05 | U17: 26.63 | Z17: 59.02 | AB17: 192.56 | AE17: 30.21 | AL17: 31.05 | AT17: 7.6 | AW17: 78 | BB17: 35 | BH17: 21.54 | BN17: 26.63 | BO17: 7.6
A18: =+'Scheduled Intervals'!A18 -> Mahindra 4500 | B18: 58.92 | F18: 18.18 | H18: 7.6 | U18: 58.92 | Z18: 27.48 | AB18: 178 | AC18: 72.73 | AE18: 18.18 | AL18: 55.98 | AT18: 7.6 | AW18: 38.25 | BB18: 38 | BC18: 37 | BH18: 33.45 | BN18: 58.92 | BO18: 7.6
A19: =+'Scheduled Intervals'!A19 -> Mahindra 5500 | B19: 58.92 | F19: 40.15 | H19: 7.6 | U19: 58.92 | Z19: 58.62 | AB19: 222.5 | AC19: 40.15 | AI19: 262.65 | AL19: 55.98 | AT19: 7.6 | BB19: 63.7 | BC19: 29.29 | BH19: 33.45 | BN19: 58.92 | BO19: 7.6
A20: =+'Scheduled Intervals'!A20 -> Mahindra 6000 | B20: 58.92 | F20: 70.71 | H20: 7.6 | U20: 58.92 | Z20: 27.48 | AB20: 262.55 | AC20: 70.71 | AI20: 311.01 | AL20: 55.98 | AT20: 7.6 | AW20: 156 | BB20: 48.48 | BC20: 34.34 | BH20: 33.45 | BN20: 58.92 | BO20: 7.6
A21: =+'Scheduled Intervals'!A21 -> Takeuchi TL 8/10/12 | B21: 77.114 | F21: 55.82 | H21: 7.6 | M21: 55.82 | P21: 30.44 | U21: 77.114 | V21: 66.15 | X21: 20.94 | Z21: 24.47 | AG21: 59.12 | AH21: 24.35 | AI21: 540.3 | AL21: 24.84 | AT21: 7.6 | AW21: 108.23 | BB21: 64.16 | BH21: 43.08 | BN21: 77.114 | BO21: 7.6
A22: =+'Scheduled Intervals'!A22 -> Takeuchi 228-235-250 | B22: 77.11 | H22: 7.6 | Q22: 83.47 | R22: 12.42 | U22: 40.91 | X22: 16.83 | Z22: 35.43 | AB22: 449.45 | AF22: 13.73 | AG22: 59.12 | AH22: 24.35 | AJ22: 12.42 | AT22: 7.6 | AW22: 108.23 | BB22: 11.22 | BC22: 10.65 | BH22: 21.54 | BN22: 40.91 | BO22: 7.6
A23: =+'Scheduled Intervals'!A23 -> Takeuchi 260 | B23: 77.11 | H23: 7.6 | Q23: 86.26 | R23: 12.42 | U23: 40.43 | X23: 37.52 | Z23: 37.92 | AB23: 427.2 | AF23: 16.15 | AG23: 55.82 | AH23: 30.44 | AL23: 12.42 | AT23: 7.6 | AW23: 25.31 | BB23: 18.24 | BC23: 72.4 | BH23: 32.31 | BN23: 40.43 | BO23: 7.6
A24: =+'Scheduled Intervals'!A24 -> Takeuchi 335 | B24: 77.11 | H24: 7.6 | Q24: 83.47 | U24: 77.11 | X24: 17.77 | Z24: 13.86 | AB24: 293.7 | AF24: 16.15 | AG24: 55.27 | AH24: 24.35 | AT24: 7.6 | AW24: 108.23 | AZ24: 23.12 | BB24: 18.11 | BC24: 34.17 | BH24: 32.31 | BN24: 77.11 | BO24: 7.6
A25: =+'Scheduled Intervals'!A25 -> Sany SY up to 35 | B25: 47.05 | H25: 7.6 | Q25: 75.74 | R25: 12.42 | U25: 47.05 | X25: 17.14 | Z25: 19.75 | AF25: 22.51 | AG25: 75.74 | AH25: 17.22 | AI25: 191.35 | AK25: 12.42 | AT25: 7.6 | BB25: 37.07 | BH25: 21.54 | BN25: 47.05 | BO25: 7.6
A26: =+'Scheduled Intervals'!A26 -> Sany SY up to 60 | B26: 55.35 | H26: 7.6 | Q26: 75.74 | R26: 12.42 | U26: 55.35 | X26: 54.61 | Z26: 19.75 | AF26: 22.51 | AG26: 75.74 | AH26: 17.22 | AI26: 452.45 | AK26: 12.42 | AT26: 7.6 | BB26: 37.07 | BH26: 21.54 | BN26: 55.35 | BO26: 7.6
A27: =+'Scheduled Intervals'!A27 -> Sany SY up to 155 | B27: 80.25 | H27: 7.6 | Q27: 75.74 | U27: 80.25 | Z27: 19.75 | AF27: 22.51 | AG27: 75.74 | AH27: 17.22 | AI27: 536.97 | AK27: 37.32 | AT27: 7.6 | BB27: 120.91 | BH27: 64.62 | BK27: 239.84 | BN27: 80.25 | BO27: 7.6
A28: =+'Scheduled Intervals'!A28 -> Sany SY up to 215 | B28: 134.2 | H28: 7.6 | Q28: 75.74 | R28: 17.22 | U28: 134.2 | Z28: 92.12 | AF28: 22.51 | AG28: 75.74 | AH28: 17.22 | AI28: 1076.9 | AJ28: 62.2 | AT28: 7.6 | BB28: 120.91 | BH28: 86.16 | BK28: 341.55 | BN28: 134.2 | BO28: 7.6
A29: =+'Scheduled Intervals'!A29 -> Sany SY up to 500 | B29: 168.64 | H29: 7.6 | Q29: 75.74 | R29: 27.25 | U29: 168.64 | Z29: 54.61 | AF29: 54.24 | AG29: 75.74 | AH29: 17.22 | AI29: 1629.25 | AJ29: 31.1 | AT29: 7.6 | BB29: 242.31 | BC29: 116.26 | BH29: 140.01 | BK29: 467.21 | BM29: 74.64 | BN29: 168.64 | BO29: 7.6
A30: =+'Scheduled Intervals'!A30 -> Sany SW up to 305 | B30: 97.68 | E30: 284.24 | H30: 7.6 | K30: 166.7 | M30: 75.74 | N30: 460.28 | U30: 97.68 | Z30: 166.7 | AB30: 195.8 | AC30: 84.44 | AF30: 18.36 | AG30: 75.74 | AH30: 7.78 | AI30: 657.12 | AJ30: 460.28 | AT30: 7.6 | BB30: 221.04 | BC30: 169.55 | BH30: 96.93 | BK30: 411.72 | BL30: 188.21 | BN30: 97.68 | BO30: 7.6
A31: =+'Scheduled Intervals'!A31 -> SCL - DIESEL | B31: 30.85 | F31: 18.59 | H31: 7.6 | U31: 30.85 | X31: 36.35 | Z31: 18.18 | AB31: 57.85 | AC31: 36.19 | AE31: 18.59 | AT31: 7.6 | AW31: 85.4 | BB31: 21.18 | BC31: 16.25 | BH31: 21.54 | BN31: 30.85 | BO31: 7.6
A32: =+'Scheduled Intervals'!A32 -> SCL - Gas | B32: 19.25 | H32: 7.6 | S32: 24.48 | U32: 19.25 | Z32: 10.4 | AB32: 13.35 | AC32: 11.13 | AT32: 7.6 | BB32: 27.09 | BD32: 1.17 | BH32: 21.54 | BN32: 19.25 | BO32: 7.6
A33: =+'Scheduled Intervals'!A33 -> Mini Excavator | B33: 25.22 | F33: 51.04 | H33: 7.6 | U33: 25.22 | Z33: 13.72 | AF33: 10.96 | AG33: 51.04 | AI33: 106.8 | AT33: 7.6 | BB33: 22.88 | BC33: 18.51 | BH33: 21.45 | BN33: 25.22 | BO33: 7.6
A34: =+'Scheduled Intervals'!A34 -> Sub Compact BX | B34: 45.97 | H34: 7.6 | U34: 45.97 | V34: 39.14 | Z34: 25.59 | AB34: 191.35 | AC34: 37.44 | AE34: 37.44 | AG34: 52.66 | AL34: 43.54 | AT34: 7.6 | BB34: 20.97 | BC34: 16.09 | BH34: 21.45 | BN34: 45.97 | BO34: 7.6
B37: ='Scheduled Intervals'!B4 -> 50 | C37: ='Scheduled Intervals'!C4 -> 0 | D37: ='Scheduled Intervals'!D4 -> 0 | E37: ='Scheduled Intervals'!E4 -> 0 | F37: ='Scheduled Intervals'!F4 -> 50 | G37: ='Scheduled Intervals'!G4 -> 0 | H37: ='Scheduled Intervals'!H4 -> 50 | I37: ='Scheduled Intervals'!I4 -> 50 | ... AC37: ='Scheduled Intervals'!AC4 -> 200 | AE37: ='Scheduled Intervals'!AE4 -> 200 | AF37: ='Scheduled Intervals'!AF4 -> 0 | AG37: ='Scheduled Intervals'!AG4 -> 0 | AH37: ='Scheduled Intervals'!AH4 -> 0 | AI37: ='Scheduled Intervals'!AI4 -> 200 | AJ37: ='Scheduled Intervals'!AJ4 -> 0 | AK37: ='Scheduled Intervals'!AK4 -> 0 | AL37: ='Scheduled Intervals'!AL4 -> 400 | ... BP37: ='Scheduled Intervals'!BP4 -> Annual
B38: ='Scheduled Intervals'!B5 -> 8 | C38: ='Scheduled Intervals'!C5 -> 0 | D38: ='Scheduled Intervals'!D5 -> 0 | E38: ='Scheduled Intervals'!E5 -> 0 | F38: ='Scheduled Intervals'!F5 -> 0 | G38: ='Scheduled Intervals'!G5 -> 0 | H38: ='Scheduled Intervals'!H5 -> 50 | I38: ='Scheduled Intervals'!I5 -> 50 | ... AC38: ='Scheduled Intervals'!AC5 -> 400 | AE38: ='Scheduled Intervals'!AE5 -> 0 | AF38: ='Scheduled Intervals'!AF5 -> 0 | AG38: ='Scheduled Intervals'!AG5 -> 0 | AH38: ='Scheduled Intervals'!AH5 -> 0 | AI38: ='Scheduled Intervals'!AI5 -> 0 | AJ38: ='Scheduled Intervals'!AJ5 -> 0 | AK38: ='Scheduled Intervals'!AK5 -> 0 | AL38: ='Scheduled Intervals'!AL5 -> 0 | ... BP38: ='Scheduled Intervals'!BP5 -> Annual
B39: ='Scheduled Intervals'!B6 -> 50 | C39: ='Scheduled Intervals'!C6 -> 0 | D39: ='Scheduled Intervals'!D6 -> 0 | E39: ='Scheduled Intervals'!E6 -> 0 | F39: ='Scheduled Intervals'!F6 -> 50 | G39: ='Scheduled Intervals'!G6 -> 0 | H39: ='Scheduled Intervals'!H6 -> 50 | I39: ='Scheduled Intervals'!I6 -> 50 | ... AC39: ='Scheduled Intervals'!AC6 -> 200 | AE39: ='Scheduled Intervals'!AE6 -> 400 | AF39: ='Scheduled Intervals'!AF6 -> 0 | AG39: ='Scheduled Intervals'!AG6 -> 0 | AH39: ='Scheduled Intervals'!AH6 -> 0 | AI39: ='Scheduled Intervals'!AI6 -> 0 | AJ39: ='Scheduled Intervals'!AJ6 -> 0 | AK39: ='Scheduled Intervals'!AK6 -> 0 | AL39: ='Scheduled Intervals'!AL6 -> 0 | ... BP39: ='Scheduled Intervals'!BP6 -> Annual
B40: ='Scheduled Intervals'!B7 -> 50 | C40: ='Scheduled Intervals'!C7 -> 0 | D40: ='Scheduled Intervals'!D7 -> 0 | E40: ='Scheduled Intervals'!E7 -> 0 | F40: ='Scheduled Intervals'!F7 -> 50 | G40: ='Scheduled Intervals'!G7 -> 0 | H40: ='Scheduled Intervals'!H7 -> 50 | I40: ='Scheduled Intervals'!I7 -> 50 | ... AC40: ='Scheduled Intervals'!AC7 -> 200 | AE40: ='Scheduled Intervals'!AE7 -> 400 | AF40: ='Scheduled Intervals'!AF7 -> 0 | AG40: ='Scheduled Intervals'!AG7 -> 0 | AH40: ='Scheduled Intervals'!AH7 -> 0 | AI40: ='Scheduled Intervals'!AI7 -> 0 | AJ40: ='Scheduled Intervals'!AJ7 -> 0 | AK40: ='Scheduled Intervals'!AK7 -> 0 | AL40: ='Scheduled Intervals'!AL7 -> 800 | ... BP40: ='Scheduled Intervals'!BP7 -> Annual
B41: ='Scheduled Intervals'!B8 -> 50 | C41: ='Scheduled Intervals'!C8 -> 0 | D41: ='Scheduled Intervals'!D8 -> 0 | E41: ='Scheduled Intervals'!E8 -> 0 | F41: ='Scheduled Intervals'!F8 -> 50 | G41: ='Scheduled Intervals'!G8 -> 0 | H41: ='Scheduled Intervals'!H8 -> 50 | I41: ='Scheduled Intervals'!I8 -> 50 | ... AC41: ='Scheduled Intervals'!AC8 -> 0 | AE41: ='Scheduled Intervals'!AE8 -> 400 | AF41: ='Scheduled Intervals'!AF8 -> 0 | AG41: ='Scheduled Intervals'!AG8 -> 0 | AH41: ='Scheduled Intervals'!AH8 -> 0 | AI41: ='Scheduled Intervals'!AI8 -> 0 | AJ41: ='Scheduled Intervals'!AJ8 -> 0 | AK41: ='Scheduled Intervals'!AK8 -> 0 | AL41: ='Scheduled Intervals'!AL8 -> 800 | ... BP41: ='Scheduled Intervals'!BP8 -> Annual
B42: ='Scheduled Intervals'!B9 -> 50 | C42: ='Scheduled Intervals'!C9 -> 0 | D42: ='Scheduled Intervals'!D9 -> 0 | E42: ='Scheduled Intervals'!E9 -> 0 | F42: ='Scheduled Intervals'!F9 -> 0 | G42: ='Scheduled Intervals'!G9 -> 0 | H42: ='Scheduled Intervals'!H9 -> 50 | I42: ='Scheduled Intervals'!I9 -> 50 | ... AC42: ='Scheduled Intervals'!AC9 -> 0 | AE42: ='Scheduled Intervals'!AE9 -> 500 | AF42: ='Scheduled Intervals'!AF9 -> 0 | AG42: ='Scheduled Intervals'!AG9 -> 0 | AH42: ='Scheduled Intervals'!AH9 -> 0 | AI42: ='Scheduled Intervals'!AI9 -> 0 | AJ42: ='Scheduled Intervals'!AJ9 -> 1000 | AK42: ='Scheduled Intervals'!AK9 -> 0 | AL42: ='Scheduled Intervals'!AL9 -> 0 | ... BP42: ='Scheduled Intervals'!BP9 -> Annual
...

Sheet Total Cost Per Service)
B1: First Service | Q1: One Time | U1: Included Maintenance Interval
A2: Category | B2: ='Hours Per Job'!B2 -> Perform Oil and Filter Change | C2: ='Hours Per Job'!C2 -> Clean Water seperator | D2: ='Hours Per Job'!D2 -> Drain Water from Fuel Tank | E2: ='Hours Per Job'!E2 -> Perform Transmission Filter and Fluid Service | F2: ='Hours Per Job'!F2 -> Change HST Oil Filter | G2: ='Hours Per Job'!G2 -> Change Hydraulic Fluid | H2: ='Hours Per Job'!H2 -> Grease Machine at required lubrication fittings | I2: ='Hours Per Job'!I2 -> Conduct Multi Point Inpection and make minor adjustments | ... BP2: ='Hours Per Job'!BP2 -> Conduct Annual Multi Point Inpection and Make Minor Adjustments
B3: ='Hours Per Job'!B3 -> Parts and Labor | C3: ='Hours Per Job'!C3 -> Labor Only | D3: ='Hours Per Job'!D3 -> Labor Only | E3: ='Hours Per Job'!E3 -> Parts and Labor | F3: ='Hours Per Job'!F3 -> Parts and Labor | G3: ='Hours Per Job'!G3 -> Parts and Labor | H3: ='Hours Per Job'!H3 -> Parts and Labor | I3: ='Hours Per Job'!I3 -> Labor Only | ... BP3: ='Hours Per Job'!BP3 -> Labor Only
A4: ='Scheduled Intervals'!A4 -> RTV | B4: =ROUND(('Hours Per Job'!B4*$B$36),2)+ROUND(('Parts Cost Per Job'!B4)*((1+$B$37)*$B$38),2) -> 89.63 | C4: =ROUND(('Hours Per Job'!C4*$B$36),2)+ROUND(('Parts Cost Per Job'!C4)*((1+$B$37)*$B$38),2) -> 0 | D4: =ROUND(('Hours Per Job'!D4*$B$36),2)+ROUND(('Parts Cost Per Job'!D4)*((1+$B$37)*$B$38),2) -> 0 | E4: =ROUND(('Hours Per Job'!E4*$B$36),2)+ROUND(('Parts Cost Per Job'!E4)*((1+$B$37)*$B$38),2) -> 0 | F4: =ROUND(('Hours Per Job'!F4*$B$36),2)+ROUND(('Parts Cost Per Job'!F4)*((1+$B$37)*$B$38),2) -> 148.69 | G4: =ROUND(('Hours Per Job'!G4*$B$36),2)+ROUND(('Parts Cost Per Job'!G4)*((1+$B$37)*$B$38),2) -> 0 | H4: =ROUND(('Hours Per Job'!H4*$B$36),2)+ROUND(('Parts Cost Per Job'!H4)*((1+$B$37)*$B$38),2) -> 23.07 | I4: =ROUND(('Hours Per Job'!I4*$B$36),2)+ROUND(('Parts Cost Per Job'!I4)*((1+$B$37)*$B$38),2) -> 30 | ... BP4: =ROUND(('Hours Per Job'!BP4*$B$36),2)+ROUND(('Parts Cost Per Job'!BP4)*((1+$B$37)*$B$38),2) -> 126
A5: ='Scheduled Intervals'!A5 -> Zero Turn Gas | B5: =ROUND(('Hours Per Job'!B5*$B$36),2)+ROUND(('Parts Cost Per Job'!B5)*((1+$B$37)*$B$38),2) -> 64.03 | C5: =ROUND(('Hours Per Job'!C5*$B$36),2)+ROUND(('Parts Cost Per Job'!C5)*((1+$B$37)*$B$38),2) -> 0 | D5: =ROUND(('Hours Per Job'!D5*$B$36),2)+ROUND(('Parts Cost Per Job'!D5)*((1+$B$37)*$B$38),2) -> 0 | E5: =ROUND(('Hours Per Job'!E5*$B$36),2)+ROUND(('Parts Cost Per Job'!E5)*((1+$B$37)*$B$38),2) -> 0 | F5: =ROUND(('Hours Per Job'!F5*$B$36),2)+ROUND(('Parts Cost Per Job'!F5)*((1+$B$37)*$B$38),2) -> 0 | G5: =ROUND(('Hours Per Job'!G5*$B$36),2)+ROUND(('Parts Cost Per Job'!G5)*((1+$B$37)*$B$38),2) -> 0 | H5: =ROUND(('Hours Per Job'!H5*$B$36),2)+ROUND(('Parts Cost Per Job'!H5)*((1+$B$37)*$B$38),2) -> 35.07 | I5: =ROUND(('Hours Per Job'!I5*$B$36),2)+ROUND(('Parts Cost Per Job'!I5)*((1+$B$37)*$B$38),2) -> 30 | ... BP5: =ROUND(('Hours Per Job'!BP5*$B$36),2)+ROUND(('Parts Cost Per Job'!BP5)*((1+$B$37)*$B$38),2) -> 126
A6: ='Scheduled Intervals'!A6 -> Zero Turn Diesel | B6: =ROUND(('Hours Per Job'!B6*$B$36),2)+ROUND(('Parts Cost Per Job'!B6)*((1+$B$37)*$B$38),2) -> 80.92 | C6: =ROUND(('Hours Per Job'!C6*$B$36),2)+ROUND(('Parts Cost Per Job'!C6)*((1+$B$37)*$B$38),2) -> 0 | D6: =ROUND(('Hours Per Job'!D6*$B$36),2)+ROUND(('Parts Cost Per Job'!D6)*((1+$B$37)*$B$38),2) -> 0 | E6: =ROUND(('Hours Per Job'!E6*$B$36),2)+ROUND(('Parts Cost Per Job'!E6)*((1+$B$37)*$B$38),2) -> 0 | F6: =ROUND(('Hours Per Job'!F6*$B$36),2)+ROUND(('Parts Cost Per Job'!F6)*((1+$B$37)*$B$38),2) -> 75.07 | G6: =ROUND(('Hours Per Job'!G6*$B$36),2)+ROUND(('Parts Cost Per Job'!G6)*((1+$B$37)*$B$38),2) -> 0 | H6: =ROUND(('Hours Per Job'!H6*$B$36),2)+ROUND(('Parts Cost Per Job'!H6)*((1+$B$37)*$B$38),2) -> 35.07 | I6: =ROUND(('Hours Per Job'!I6*$B$36),2)+ROUND(('Parts Cost Per Job'!I6)*((1+$B$37)*$B$38),2) -> 30 | ... BP6: =ROUND(('Hours Per Job'!BP6*$B$36),2)+ROUND(('Parts Cost Per Job'!BP6)*((1+$B$37)*$B$38),2) -> 126
A7: ='Scheduled Intervals'!A7 -> Compact L series | B7: =ROUND(('Hours Per Job'!B7*$B$36),2)+ROUND(('Parts Cost Per Job'!B7)*((1+$B$37)*$B$38),2) -> 93.92 | C7: =ROUND(('Hours Per Job'!C7*$B$36),2)+ROUND(('Parts Cost Per Job'!C7)*((1+$B$37)*$B$38),2) -> 0 | D7: =ROUND(('Hours Per Job'!D7*$B$36),2)+ROUND(('Parts Cost Per Job'!D7)*((1+$B$37)*$B$38),2) -> 0 | E7: =ROUND(('Hours Per Job'!E7*$B$36),2)+ROUND(('Parts Cost Per Job'!E7)*((1+$B$37)*$B$38),2) -> 0 | F7: =ROUND(('Hours Per Job'!F7*$B$36),2)+ROUND(('Parts Cost Per Job'!F7)*((1+$B$37)*$B$38),2) -> 87.07 | G7: =ROUND(('Hours Per Job'!G7*$B$36),2)+ROUND(('Parts Cost Per Job'!G7)*((1+$B$37)*$B$38),2) -> 0 | H7: =ROUND(('Hours Per Job'!H7*$B$36),2)+ROUND(('Parts Cost Per Job'!H7)*((1+$B$37)*$B$38),2) -> 35.07 | I7: =ROUND(('Hours Per Job'!I7*$B$36),2)+ROUND(('Parts Cost Per Job'!I7)*((1+$B$37)*$B$38),2) -> 30 | ... BP7: =ROUND(('Hours Per Job'!BP7*$B$36),2)+ROUND(('Parts Cost Per Job'!BP7)*((1+$B$37)*$B$38),2) -> 126
A8: ='Scheduled Intervals'!A8 -> Utility under 75 MX&M | B8: =ROUND(('Hours Per Job'!B8*$B$36),2)+ROUND(('Parts Cost Per Job'!B8)*((1+$B$37)*$B$38),2) -> 106.01 | C8: =ROUND(('Hours Per Job'!C8*$B$36),2)+ROUND(('Parts Cost Per Job'!C8)*((1+$B$37)*$B$38),2) -> 0 | D8: =ROUND(('Hours Per Job'!D8*$B$36),2)+ROUND(('Parts Cost Per Job'!D8)*((1+$B$37)*$B$38),2) -> 0 | E8: =ROUND(('Hours Per Job'!E8*$B$36),2)+ROUND(('Parts Cost Per Job'!E8)*((1+$B$37)*$B$38),2) -> 0 | F8: =ROUND(('Hours Per Job'!F8*$B$36),2)+ROUND(('Parts Cost Per Job'!F8)*((1+$B$37)*$B$38),2) -> 161.44 | G8: =ROUND(('Hours Per Job'!G8*$B$36),2)+ROUND(('Parts Cost Per Job'!G8)*((1+$B$37)*$B$38),2) -> 0 | H8: =ROUND(('Hours Per Job'!H8*$B$36),2)+ROUND(('Parts Cost Per Job'!H8)*((1+$B$37)*$B$38),2) -> 35.07 | I8: =ROUND(('Hours Per Job'!I8*$B$36),2)+ROUND(('Parts Cost Per Job'!I8)*((1+$B$37)*$B$38),2) -> 30 | ... BP8: =ROUND(('Hours Per Job'!BP8*$B$36),2)+ROUND(('Parts Cost Per Job'!BP8)*((1+$B$37)*$B$38),2) -> 126
A9: ='Scheduled Intervals'!A9 -> Utility over 75 M4 class | B9: =ROUND(('Hours Per Job'!B9*$B$36),2)+ROUND(('Parts Cost Per Job'!B9)*((1+$B$37)*$B$38),2) -> 143.66 | C9: =ROUND(('Hours Per Job'!C9*$B$36),2)+ROUND(('Parts Cost Per Job'!C9)*((1+$B$37)*$B$38),2) -> 0 | D9: =ROUND(('Hours Per Job'!D9*$B$36),2)+ROUND(('Parts Cost Per Job'!D9)*((1+$B$37)*$B$38),2) -> 0 | E9: =ROUND(('Hours Per Job'!E9*$B$36),2)+ROUND(('Parts Cost Per Job'!E9)*((1+$B$37)*$B$38),2) -> 0 | F9: =ROUND(('Hours Per Job'!F9*$B$36),2)+ROUND(('Parts Cost Per Job'!F9)*((1+$B$37)*$B$38),2) -> 0 | G9: =ROUND(('Hours Per Job'!G9*$B$36),2)+ROUND(('Parts Cost Per Job'!G9)*((1+$B$37)*$B$38),2) -> 0 | H9: =ROUND(('Hours Per Job'!H9*$B$36),2)+ROUND(('Parts Cost Per Job'!H9)*((1+$B$37)*$B$38),2) -> 35.07 | I9: =ROUND(('Hours Per Job'!I9*$B$36),2)+ROUND(('Parts Cost Per Job'!I9)*((1+$B$37)*$B$38),2) -> 30 | ... BP9: =ROUND(('Hours Per Job'!BP9*$B$36),2)+ROUND(('Parts Cost Per Job'!BP9)*((1+$B$37)*$B$38),2) -> 126
